Workbook
Name Periodo: #REF!
Name OwnerMeter: #REF!
Name owner: ECxDpto!$A$9
Name fecha: CuECxDpto!$G$3
Name department: EC!$E$9
Name Soles: #REF!
Name OwnerDpto: #REF!
Name owner: EC!$A$9
Name owner: CuECxDpto!$A$9
Name meter: ECxDpto!$G$9
Name Consumo: #REF!
Name meter: CuECxDpto!$G$9
Name meter: EC!$G$9
Name fecha: EC!$G$3
Name DPTOS: Deuda!$A$4:$A$64
Name fecha: ECxDpto!$G$3

Sheet Calculo Gas
F2: CALCULO DE GAS 2024 | T2: CALCULO DE GAS 2025 | BD2: 2026
E3: COSTO UNIT | G3: =Consumo!$E$7/'Calculo Gas'!$F$66 -> 22.335927 | I3: =Consumo!E10/'Calculo Gas'!H66 -> 17.86569 | K3: =Consumo!E13/J66 -> 12.160825 | M3: =Consumo!E17/'Calculo Gas'!L66 -> 15.610637 | O3: =Consumo!E21/'Calculo Gas'!N66 -> 15.196672 | Q3: =Consumo!E25/P66 -> 14.840947 | S3: =Consumo!E30/R66 -> 16.571528 | U3: =Consumo!E34/T66 -> 17.562064 | W3: =Consumo!E37/V66 -> 12.223474 | Y3: =Consumo!E40/X66 -> 12.134376 | AA3: =Consumo!E44/'Calculo Gas'!Z66 -> 14.086322 | AC3: =Consumo!E48/'Calculo Gas'!AB66 -> 12.847039 | AE3: =Consumo!E52/'Calculo Gas'!AD66 -> 12.578186 | AG3: =Consumo!E57/'Calculo Gas'!AF66 -> 14.247901 | AI3: =Consumo!E62/'Calculo Gas'!AH66 -> 13.913957 | AK3: =Consumo!E67/'Calculo Gas'!AJ66 -> 14.407739 | AM3: =Consumo!E71/'Calculo Gas'!AL66 -> 9.9288235 | AO3: =Consumo!E76/'Calculo Gas'!AN66 -> 16.262939 | AQ3: =Consumo!E80/'Calculo Gas'!AP66 -> 13.32323 | AS3: =Consumo!E84/'Calculo Gas'!AR66 -> 11.816926 | AU3: =Consumo!E88/'Calculo Gas'!AT66 -> 12.025193 | AW3: =Consumo!E93/'Calculo Gas'!AV66 -> 12.258453 | AY3: =Consumo!E97/'Calculo Gas'!AX66 -> 11.604064 | BA3: =Consumo!E102/'Calculo Gas'!AZ66 -> 13.804031 | BC3: =Consumo!E107/'Calculo Gas'!BB66 -> 14.985666 | BE3: =Consumo!E113/'Calculo Gas'!BD66 -> 21.615018 | BG3: =Consumo!U80/'Calculo Gas'!BF66 -> #DIV/0! | BI3: =Consumo!W80/'Calculo Gas'!BH66 -> #DIV/0! | BK3: =Consumo!Y80/'Calculo Gas'!BJ66 -> #DIV/0! | BM3: =Consumo!AA80/'Calculo Gas'!BL66 -> #DIV/0! | BO3: =Consumo!AC80/'Calculo Gas'!BN66 -> #DIV/0!
A4: Pago total x mes | B4: Consumo del mes | C4: Departam. | D4: Nombre | E4: Número de Medidor | F4: Consumo Junio | G4: Consumo Junio | H4: Consumo Julio | I4: Consumo Julio | J4: Consumo Agosto | K4: Consumo Agosto | L4: Consumo Setiembre | M4: Consumo Setiembre | N4: Consumo Octubre | O4: Consumo Octubre | P4: Consumo Noviembre | Q4: Consumo Noviembre | R4: Consumo Diciembre | S4: Consumo Diciembre | T4: Consumo ENERO | U4: Consumo ENERO | V4: Consumo FEBRERO | W4: Consumo FEBRERO | X4: Consumo MARZO | Y4: Consumo MARZO | Z4: Consumo ABRIL | AA4: Consumo ABRIL | AB4: Consumo MAYO | AC4: Consumo MAYO | AD4: Consumo Junio | AE4: Consumo Junio | AF4: Consumo Julio | AG4: Consumo Julio | AH4: Consumo Agosto | AI4: Consumo Agosto | AJ4: Consumo Setiembre | AK4: Consumo Setiembre | AL4: Consumo Octubre | AM4: Consumo Octubre | AN4: Consumo Noviembre | AO4: Consumo Noviembre | AP4: Consumo Diciembre | AQ4: Consumo Diciembre | AR4: Consumo Enero | AS4: Consumo Enero | AT4: Consumo Febrero | AU4: Consumo Febrero | AV4: Consumo Marzo | AW4: Consumo Marzo | AX4: Consumo Abril | AY4: Consumo Abril | AZ4: Consumo Mayo | BA4: Consumo Mayo | BB4: Consumo Junio | BC4: Consumo Junio | BD4: Consumo Julio | BE4: Consumo Julio | BF4: Agosto | BG4: Agosto | BH4: Septiembre | BI4: Septiembre | BJ4: Octubre | BK4: Octubre | BL4: Noviembre | BM4: Noviembre | BN4: Diciembre | BO4: Diciembre
F5: m3 | G5: Soles | H5: m3 | I5: Soles | J5: m3 | K5: Soles | L5: m3 | M5: Soles | N5: m3 | O5: Soles | P5: m3 | Q5: Soles | R5: m3 | S5: Soles | T5: m3 | U5: Soles | V5: m3 | W5: Soles | X5: m3 | Y5: Soles | Z5: m3 | AA5: Soles | AB5: m3 | AC5: Soles | AD5: m3 | AE5: Soles | AF5: m3 | AG5: Soles | AH5: m3 | AI5: Soles | AJ5: m3 | AK5: Soles | AL5: m3 | AM5: Soles | AN5: m3 | AO5: Soles | AP5: m3 | AQ5: Soles | AR5: m3 | AS5: Soles | AT5: m3 | AU5: Soles | AV5: m3 | AW5: Soles | AX5: m3 | AY5: Soles | AZ5: m3 | BA5: Soles | BB5: m3 | BC5: Soles | BD5: m3 | BE5: Soles | BF5: m3 | BG5: Soles | BH5: m3 | BI5: Soles | BJ5: m3 | BK5: Soles | BL5: m3 | BM5: Soles | BN5: m3 | BO5: Soles
A6: =ROUND(AG6,1) -> 12.5 | B6: =AF6 -> 0.876 | C6: 201 | D6: HUGO LUCIO ADUVIRE PATACA | E6: 2034049 | F6: =Lecturas!D4-Lecturas!C4 -> 0.754 | G6: =F6*$G$3 -> 16.841289 | H6: =IF((Lecturas!E4-Lecturas!D4) < 0, "", Lecturas!E4-Lecturas!D4) -> 0.611 | I6: =IFERROR(H6*$I$3,"") -> 10.915936 | J6: =IF(OR((Lecturas!F4-Lecturas!E4) <= 0), "", Lecturas!F4-Lecturas!E4) -> 0.601 | K6: =IFERROR(J6*$K$3,"") -> 7.3086558 | L6: =IF(OR((Lecturas!G4-Lecturas!F4) <= 0), "", Lecturas!G4-Lecturas!F4) -> 0.867 | M6: =IFERROR(L6*$M$3,"") -> 13.534422 | N6: =IF(OR((Lecturas!H4-Lecturas!G4) <= 0), "", Lecturas!H4-Lecturas!G4) -> 0.583 | O6: =IFERROR(N6*$O$3,"") -> 8.8596599 | P6: =IF(OR((Lecturas!I4-Lecturas!H4) <= 0), "", Lecturas!I4-Lecturas!H4) -> 0.663 | Q6: =IFERROR(P6*$Q$3,"") -> 9.8395478 | R6: =IF(OR((Lecturas!J4-Lecturas!I4) <= 0), "", Lecturas!J4-Lecturas!I4) -> 0.502 | S6: =IFERROR(R6*$S$3,"") -> 8.3189069 | T6: =IF(OR((Lecturas!K4-Lecturas!J4) <= 0), "", Lecturas!K4-Lecturas!J4) -> 0.359 | U6: =IFERROR(T6*$U$3,"") -> 6.3047809 | V6: =IF(OR((Lecturas!L4-Lecturas!K4) <= 0), "", Lecturas!L4-Lecturas!K4) -> 0.394 | W6: =IFERROR(V6*$W$3,"") -> 4.8160489 | X6: =IF(OR((Lecturas!M4-Lecturas!L4) < 0), "", Lecturas!M4-Lecturas!L4) -> 0.181 | Y6: =IFERROR(X6*$Y$3,"") -> 2.1963221 | Z6: =IF(OR((Lecturas!N4-Lecturas!M4) <= 0), "", Lecturas!N4-Lecturas!M4) -> 0.496 | AA6: =IFERROR(Z6*$AA$3,"") -> 6.9868155 | AB6: =IF(OR((Lecturas!O4-Lecturas!N4) < 0), "", Lecturas!O4-Lecturas!N4) -> 0.901 | AC6: =IFERROR(AB6*$AC$3,"") -> 11.575182 | AD6: =IF(OR((Lecturas!P4-Lecturas!O4) < 0), "", Lecturas!P4-Lecturas!O4) -> 0.966 | AE6: =IFERROR(AD6*$AE$3,"") -> 12.150528 | AF6: =IF((Lecturas!Q4-Lecturas!P4)<= 0,"",Lecturas!Q4-Lecturas!P4) -> 0.876 | AG6: =IFERROR(AF6*$AG$3,"") -> 12.481161 | AH6: =IF((Lecturas!R4-Lecturas!Q4)<= 0,"",Lecturas!R4-Lecturas!Q4) -> 0.735 | AI6: =IFERROR(AH6*$AI$3,"") -> 10.226758 | AJ6: =IF((Lecturas!S4-Lecturas!R4)<= 0,"",Lecturas!S4-Lecturas!R4) -> 0.894 | AK6: =IFERROR(AJ6*$AK$3,"") -> 12.880519 | AL6: =IF((Lecturas!T4-Lecturas!S4)<= 0,"",Lecturas!T4-Lecturas!S4) -> 1.271 | AM6: =IFERROR(AL6*$AM$3,"") -> 12.619535 | AN6: =IF((Lecturas!U4-Lecturas!T4)<= 0,"",Lecturas!U4-Lecturas!T4) -> 0.102 | AO6: =IFERROR(AN6*$AO$3,"") -> 1.6588198 | AP6: =IF((Lecturas!V4-Lecturas!U4)<= 0,"",Lecturas!V4-Lecturas!U4) -> 0.043 | AQ6: =IFERROR(AP6*$AQ$3,"") -> 0.57289888 | AR6: =IF((Lecturas!W4-Lecturas!V4)<= 0,"",Lecturas!W4-Lecturas!V4) -> 0.215 | AS6: =IFERROR(AR6*$AS$3,"") -> 2.5406391 | AT6: =IF((Lecturas!X4-Lecturas!W4)<= 0,"",Lecturas!X4-Lecturas!W4) -> 0.128 | AU6: =IFERROR(AT6*$AU$3,"") -> 1.5392247 | AV6: =IF((Lecturas!Y4-Lecturas!X4)<= 0,"",Lecturas!Y4-Lecturas!X4) -> 0.087 | AW6: =IFERROR(AV6*$AW$3,"") -> 1.0664854 | AX6: =IF((Lecturas!Z4-Lecturas!Y4)<= 0,"0",Lecturas!Z4-Lecturas!Y4) -> 0.218 | AY6: =IFERROR(AX6*$AY$3,"0") -> 2.529686 | AZ6: =IF((Lecturas!AA4-Lecturas!Z4)<= 0,"0",Lecturas!AA4-Lecturas!Z4) -> 0.187 | BA6: =IFERROR(AZ6*$BA$3,"0") -> 2.5813538 | BB6: =IF((Lecturas!AB4-Lecturas!AA4)<= 0,"0",Lecturas!AB4-Lecturas!AA4) -> 0.094 | BC6: =IFERROR(BB6*$BC$3,"0") -> 1.4086526 | BD6: =IF((Lecturas!AC4-Lecturas!AB4)<= 0,"0",Lecturas!AC4-Lecturas!AB4) -> 0.254 | BE6: =IFERROR(BD6*$BE$3,"0") -> 5.4902145 | BF6: =IF((Lecturas!AD4-Lecturas!AC4)<= 0,"0",Lecturas!AD4-Lecturas!AC4) -> 0 | BG6: =IFERROR(BF6*$BG$3,"0") -> 0 | BH6: =IF((Lecturas!AE4-Lecturas!AD4)<= 0,"0",Lecturas!AE4-Lecturas!AD4) -> 0 | BI6: =IFERROR(BH6*$BI$3,"0") -> 0 | BJ6: =IF((Lecturas!AF4-Lecturas!AE4)<= 0,"0",Lecturas!AF4-Lecturas!AE4) -> 0 | BK6: =IFERROR(BJ6*$BK$3,"0") -> 0 | BL6: =IF((Lecturas!AG4-Lecturas!AF4)<= 0,"0",Lecturas!AG4-Lecturas!AF4) -> 0 | BM6: =IFERROR(BL6*$BM$3,"0") -> 0 | BN6: =IF((Lecturas!AH4-Lecturas!AG4)<= 0,"0",Lecturas!AH4-Lecturas!AG4) -> 0 | BO6: =IFERROR(BN6*$BO$3,"0") -> 0
A7: =ROUND(AG7,1) -> 22.3 | B7: =AF7 -> 1.564 | C7: 202 | D7: ELISABETH POTERICO HUAMAYALLI | E7: 2034056 | F7: =Lecturas!D5-Lecturas!C5 -> 0.847 | G7: =F7*$G$3 -> 18.91853 | H7: =IF((Lecturas!E5-Lecturas!D5) < 0, "", Lecturas!E5-Lecturas!D5) -> 0.608 | I7: =IFERROR(H7*$I$3,"") -> 10.862339 | J7: =IF(OR((Lecturas!F5-Lecturas!E5) <= 0), "", Lecturas!F5-Lecturas!E5) -> 0.915 | K7: =IFERROR(J7*$K$3,"") -> 11.127155 | L7: =IF(OR((Lecturas!G5-Lecturas!F5) <= 0), "", Lecturas!G5-Lecturas!F5) -> 0.576 | M7: =IFERROR(L7*$M$3,"") -> 8.9917267 | N7: =IF(OR((Lecturas!H5-Lecturas!G5) <= 0), "", Lecturas!H5-Lecturas!G5) -> 0.738 | O7: =IFERROR(N7*$O$3,"") -> 11.215144 | P7: =IF(OR((Lecturas!I5-Lecturas!H5) <= 0), "", Lecturas!I5-Lecturas!H5) -> 0.701 | Q7: =IFERROR(P7*$Q$3,"") -> 10.403504 | R7: =IF(OR((Lecturas!J5-Lecturas!I5) <= 0), "", Lecturas!J5-Lecturas!I5) -> 0.189 | S7: =IFERROR(R7*$S$3,"") -> 3.1320187 | T7: =IF(OR((Lecturas!K5-Lecturas!J5) <= 0), "", Lecturas!K5-Lecturas!J5) -> 0.562 | U7: =IFERROR(T7*$U$3,"") -> 9.8698799 | V7: =IF(OR((Lecturas!L5-Lecturas!K5) <= 0), "", Lecturas!L5-Lecturas!K5) -> 1.962 | W7: =IFERROR(V7*$W$3,"") -> 23.982457 | X7: =IF(OR((Lecturas!M5-Lecturas!L5) < 0), "", Lecturas!M5-Lecturas!L5) -> 1.805 | Y7: =IFERROR(X7*$Y$3,"") -> 21.902549 | Z7: =IF(OR((Lecturas!N5-Lecturas!M5) <= 0), "", Lecturas!N5-Lecturas!M5) -> 1.727 | AA7: =IFERROR(Z7*$AA$3,"") -> 24.327078 | AB7: =IF(OR((Lecturas!O5-Lecturas!N5) < 0), "", Lecturas!O5-Lecturas!N5) -> 1.681 | AC7: =IFERROR(AB7*$AC$3,"") -> 21.595873 | AD7: =IF(OR((Lecturas!P5-Lecturas!O5) < 0), "", Lecturas!P5-Lecturas!O5) -> 1.287 | AE7: =IFERROR(AD7*$AE$3,"") -> 16.188126 | AF7: =IF((Lecturas!Q5-Lecturas!P5)<= 0,"",Lecturas!Q5-Lecturas!P5) -> 1.564 | AG7: =IFERROR(AF7*$AG$3,"") -> 22.283717 | AH7: =IF((Lecturas!R5-Lecturas!Q5)<= 0,"",Lecturas!R5-Lecturas!Q5) -> 1.851 | AI7: =IFERROR(AH7*$AI$3,"") -> 25.754734 | AJ7: =IF((Lecturas!S5-Lecturas!R5)<= 0,"",Lecturas!S5-Lecturas!R5) -> 1.715 | AK7: =IFERROR(AJ7*$AK$3,"") -> 24.709272 | AL7: =IF((Lecturas!T5-Lecturas!S5)<= 0,"",Lecturas!T5-Lecturas!S5) -> 0.02 | AM7: =IFERROR(AL7*$AM$3,"") -> 0.19857647 | AN7: =IF((Lecturas!U5-Lecturas!T5)<= 0,"",Lecturas!U5-Lecturas!T5) -> 0.005 | AO7: =IFERROR(AN7*$AO$3,"") -> 0.081314696 | AP7: =IF((Lecturas!V5-Lecturas!U5)<= 0,"",Lecturas!V5-Lecturas!U5) -> 0.742 | AQ7: =IFERROR(AP7*$AQ$3,"") -> 9.8858366 | AR7: =IF((Lecturas!W5-Lecturas!V5)<= 0,"",Lecturas!W5-Lecturas!V5) -> 1.196 | AS7: =IFERROR(AR7*$AS$3,"") -> 14.133044 | AT7: =IF((Lecturas!X5-Lecturas!W5)<= 0,"",Lecturas!X5-Lecturas!W5) -> 1.543 | AU7: =IFERROR(AT7*$AU$3,"") -> 18.554872 | AV7: =IF((Lecturas!Y5-Lecturas!X5)<= 0,"",Lecturas!Y5-Lecturas!X5) -> 0.952 | AW7: =IFERROR(AV7*$AW$3,"") -> 11.670047 | AX7: =IF((Lecturas!Z5-Lecturas!Y5)<= 0,"0",Lecturas!Z5-Lecturas!Y5) -> 0.022 | AY7: =IFERROR(AX7*$AY$3,"0") -> 0.25528941 | AZ7: =IF((Lecturas!AA5-Lecturas!Z5)<= 0,"0",Lecturas!AA5-Lecturas!Z5) -> 0 | BA7: =IFERROR(AZ7*$BA$3,"0") -> 0 | BB7: =IF((Lecturas!AB5-Lecturas!AA5)<= 0,"0",Lecturas!AB5-Lecturas!AA5) -> 0.004 | BC7: =IFERROR(BB7*$BC$3,"0") -> 0.059942664 | BD7: =IF((Lecturas!AC5-Lecturas!AB5)<= 0,"0",Lecturas!AC5-Lecturas!AB5) -> 0.028 | BE7: =IFERROR(BD7*$BE$3,"0") -> 0.6052205 | BF7: =IF((Lecturas!AD5-Lecturas!AC5)<= 0,"0",Lecturas!AD5-Lecturas!AC5) -> 0 | BG7: =IFERROR(BF7*$BG$3,"0") -> 0 | BH7: =IF((Lecturas!AE5-Lecturas!AD5)<= 0,"0",Lecturas!AE5-Lecturas!AD5) -> 0 | BI7: =IFERROR(BH7*$BI$3,"0") -> 0 | BJ7: =IF((Lecturas!AF5-Lecturas!AE5)<= 0,"0",Lecturas!AF5-Lecturas!AE5) -> 0 | BK7: =IFERROR(BJ7*$BK$3,"0") -> 0 | BL7: =IF((Lecturas!AG5-Lecturas!AF5)<= 0,"0",Lecturas!AG5-Lecturas!AF5) -> 0 | BM7: =IFERROR(BL7*$BM$3,"0") -> 0 | BN7: =IF((Lecturas!AH5-Lecturas!AG5)<= 0,"0",Lecturas!AH5-Lecturas!AG5) -> 0 | BO7: =IFERROR(BN7*$BO$3,"0") -> 0
A8: =ROUND(AG8,1) -> 0 | B8: =AF8 -> 0 | C8: 203 | D8: SANTIAGO MORAN VASQUEZ | E8: 2034020 | F8: =Lecturas!D6-Lecturas!C6 -> 0.018 | G8: =F8*$G$3 -> 0.40204669 | H8: =IF((Lecturas!E6-Lecturas!D6) < 0, "", Lecturas!E6-Lecturas!D6) -> 0.674 | I8: =IFERROR(H8*$I$3,"") -> 12.041475 | J8: =IF(OR((Lecturas!F6-Lecturas!E6) <= 0), "", Lecturas!F6-Lecturas!E6) -> 0.911 | K8: =IFERROR(J8*$K$3,"") -> 11.078512 | L8: =IF(OR((Lecturas!G6-Lecturas!F6) < 0), "", Lecturas!G6-Lecturas!F6) -> 0 | M8: =IFERROR(L8*$M$3,"") -> 0 | N8: =IF(OR((Lecturas!H6-Lecturas!G6) < 0), "", Lecturas!H6-Lecturas!G6) -> 0 | O8: =IFERROR(N8*$O$3,"") -> 0 | P8: =IF(OR((Lecturas!I6-Lecturas!H6) <= 0), "", Lecturas!I6-Lecturas!H6) -> 0.318 | Q8: =IFERROR(P8*$Q$3,"") -> 4.7194211 | R8: =IF(OR((Lecturas!J6-Lecturas!I6) <= 0), "", Lecturas!J6-Lecturas!I6) -> 0.001 | S8: =IFERROR(R8*$S$3,"") -> 0.016571528 | T8: =IF(OR((Lecturas!K6-Lecturas!J6) < 0), "", Lecturas!K6-Lecturas!J6) -> 0 | U8: =IFERROR(T8*$U$3,"") -> 0 | V8: =IF(OR((Lecturas!L6-Lecturas!K6) <0), "", Lecturas!L6-Lecturas!K6) -> 0 | W8: =IFERROR(V8*$W$3,"") -> 0 | X8: =IF(OR((Lecturas!M6-Lecturas!L6) < 0), "", Lecturas!M6-Lecturas!L6) -> 0 | Y8: =IFERROR(X8*$Y$3,"") -> 0 | Z8: =IF(OR((Lecturas!N6-Lecturas!M6) <0), "", Lecturas!N6-Lecturas!M6) -> 0 | AA8: =IFERROR(Z8*$AA$3,"") -> 0 | AB8: =IF(OR((Lecturas!O6-Lecturas!N6) < 0), "", Lecturas!O6-Lecturas!N6) -> 0 | AC8: =IFERROR(AB8*$AC$3,"") -> 0 | AD8: =IF(OR((Lecturas!P6-Lecturas!O6) < 0), "", Lecturas!P6-Lecturas!O6) -> 0 | AE8: =IFERROR(AD8*$AE$3,"") -> 0 | AF8: =IF((Lecturas!Q6-Lecturas!P6)< 0,"",Lecturas!Q6-Lecturas!P6) -> 0 | AG8: =IFERROR(AF8*$AG$3,"") -> 0 | AH8: =IF((Lecturas!R6-Lecturas!Q6)<= 0,"",Lecturas!R6-Lecturas!Q6) -> 0.36 | AI8: =IFERROR(AH8*$AI$3,"") -> 5.0090244 | AJ8: =IF((Lecturas!S6-Lecturas!R6)<= 0,"",Lecturas!S6-Lecturas!R6) -> 0.008 | AK8: =IFERROR(AJ8*$AK$3,"") -> 0.11526191 | AL8: =IF((Lecturas!T6-Lecturas!S6)<= 0,"",Lecturas!T6-Lecturas!S6) -> 0.005 | AM8: =IFERROR(AL8*$AM$3,"") -> 0.049644117 | AN8: =IF((Lecturas!U6-Lecturas!T6)<= 0,"",Lecturas!U6-Lecturas!T6) -> 0.003 | AO8: =IFERROR(AN8*$AO$3,"") -> 0.048788818 | AP8: =IF((Lecturas!V6-Lecturas!U6)<= 0,"",Lecturas!V6-Lecturas!U6) -> 0.127 | AQ8: =IFERROR(AP8*$AQ$3,"") -> 1.6920502 | AR8: =IF((Lecturas!W6-Lecturas!V6)<= 0,"",Lecturas!W6-Lecturas!V6) -> 0.231 | AS8: =IFERROR(AR8*$AS$3,"") -> 2.72971 | AT8: =IF((Lecturas!X6-Lecturas!W6)<= 0,"",Lecturas!X6-Lecturas!W6) -> 0.114 | AU8: =IFERROR(AT8*$AU$3,"") -> 1.370872 | AV8: =IF((Lecturas!Y6-Lecturas!X6)<= 0,"",Lecturas!Y6-Lecturas!X6) -> 0.002 | AW8: =IFERROR(AV8*$AW$3,"") -> 0.024516906 | AX8: =IF((Lecturas!Z6-Lecturas!Y6)<= 0,"0",Lecturas!Z6-Lecturas!Y6) -> 0.003 | AY8: =IFERROR(AX8*$AY$3,"0") -> 0.034812192 | AZ8: =IF((Lecturas!AA6-Lecturas!Z6)<= 0,"0",Lecturas!AA6-Lecturas!Z6) -> 0 | BA8: =IFERROR(AZ8*$BA$3,"0") -> 0 | BB8: =IF((Lecturas!AB6-Lecturas!AA6)<= 0,"0",Lecturas!AB6-Lecturas!AA6) -> 0.004 | BC8: =IFERROR(BB8*$BC$3,"0") -> 0.059942664 | BD8: =IF((Lecturas!AC6-Lecturas!AB6)<= 0,"0",Lecturas!AC6-Lecturas!AB6) -> 0.04 | BE8: =IFERROR(BD8*$BE$3,"0") -> 0.86460071 | BF8: =IF((Lecturas!AD6-Lecturas!AC6)<= 0,"0",Lecturas!AD6-Lecturas!AC6) -> 0 | BG8: =IFERROR(BF8*$BG$3,"0") -> 0 | BH8: =IF((Lecturas!AE6-Lecturas!AD6)<= 0,"0",Lecturas!AE6-Lecturas!AD6) -> 0 | BI8: =IFERROR(BH8*$BI$3,"0") -> 0 | BJ8: =IF((Lecturas!AF6-Lecturas!AE6)<= 0,"0",Lecturas!AF6-Lecturas!AE6) -> 0 | BK8: =IFERROR(BJ8*$BK$3,"0") -> 0 | BL8: =IF((Lecturas!AG6-Lecturas!AF6)<= 0,"0",Lecturas!AG6-Lecturas!AF6) -> 0 | BM8: =IFERROR(BL8*$BM$3,"0") -> 0 | BN8: =IF((Lecturas!AH6-Lecturas!AG6)<= 0,"0",Lecturas!AH6-Lecturas!AG6) -> 0 | BO8: =IFERROR(BN8*$BO$3,"0") -> 0
A9: =ROUND(AG9,1) -> 12.3 | B9: =AF9 -> 0.86 | C9: 204 | D9: LILIA ISABEL GIL ARAUJO | E9: 2034040 | F9: =Lecturas!D7-Lecturas!C7 -> 0.185 | G9: =F9*$G$3 -> 4.1321465 | H9: =IF((Lecturas!E7-Lecturas!D7) < 0, "", Lecturas!E7-Lecturas!D7) -> 0.138 | I9: =IFERROR(H9*$I$3,"") -> 2.4654652 | J9: =IF(OR((Lecturas!F7-Lecturas!E7) < 0), "", Lecturas!F7-Lecturas!E7) -> 0 | K9: =IFERROR(J9*$K$3,"") -> 0 | L9: =IF(OR((Lecturas!G7-Lecturas!F7) <= 0), "", Lecturas!G7-Lecturas!F7) -> 0.296 | M9: =IFERROR(L9*$M$3,"") -> 4.6207484 | N9: =IF(OR((Lecturas!H7-Lecturas!G7) <= 0), "", Lecturas!H7-Lecturas!G7) -> 0.183 | O9: =IFERROR(N9*$O$3,"") -> 2.780991 | P9: =IF(OR((Lecturas!I7-Lecturas!H7) <= 0), "", Lecturas!I7-Lecturas!H7) -> 0.214 | Q9: =IFERROR(P9*$Q$3,"") -> 3.1759626 | R9: =IF(OR((Lecturas!J7-Lecturas!I7) <= 0), "", Lecturas!J7-Lecturas!I7) -> 0.324 | S9: =IFERROR(R9*$S$3,"") -> 5.369175 | T9: =IF(OR((Lecturas!K7-Lecturas!J7) <= 0), "", Lecturas!K7-Lecturas!J7) -> 0.513 | U9: =IFERROR(T9*$U$3,"") -> 9.0093388 | V9: =IF(OR((Lecturas!L7-Lecturas!K7) <= 0), "", Lecturas!L7-Lecturas!K7) -> 0.524 | W9: =IFERROR(V9*$W$3,"") -> 6.4051006 | X9: =IF(OR((Lecturas!M7-Lecturas!L7) < 0), "", Lecturas!M7-Lecturas!L7) -> 0.443 | Y9: =IFERROR(X9*$Y$3,"") -> 5.3755287 | Z9: =IF(OR((Lecturas!N7-Lecturas!M7) <= 0), "", Lecturas!N7-Lecturas!M7) -> 0.811 | AA9: =IFERROR(Z9*$AA$3,"") -> 11.424007 | AB9: =IF(OR((Lecturas!O7-Lecturas!N7) < 0), "", Lecturas!O7-Lecturas!N7) -> 0.749 | AC9: =IFERROR(AB9*$AC$3,"") -> 9.6224323 | AD9: =IF(OR((Lecturas!P7-Lecturas!O7) < 0), "", Lecturas!P7-Lecturas!O7) -> 0.811 | AE9: =IFERROR(AD9*$AE$3,"") -> 10.200909 | AF9: =IF((Lecturas!Q7-Lecturas!P7)<= 0,"",Lecturas!Q7-Lecturas!P7) -> 0.86 | AG9: =IFERROR(AF9*$AG$3,"") -> 12.253195 | AH9: =IF((Lecturas!R7-Lecturas!Q7)<= 0,"",Lecturas!R7-Lecturas!Q7) -> 0.706 | AI9: =IFERROR(AH9*$AI$3,"") -> 9.8232534 | AJ9: =IF((Lecturas!S7-Lecturas!R7)<= 0,"",Lecturas!S7-Lecturas!R7) -> 0.164 | AK9: =IFERROR(AJ9*$AK$3,"") -> 2.3628692 | AL9: =IF((Lecturas!T7-Lecturas!S7)<= 0,"",Lecturas!T7-Lecturas!S7) -> 1.253 | AM9: =IFERROR(AL9*$AM$3,"") -> 12.440816 | AN9: =IF((Lecturas!U7-Lecturas!T7)<= 0,"",Lecturas!U7-Lecturas!T7) -> 0.386 | AO9: =IFERROR(AN9*$AO$3,"") -> 6.2774945 | AP9: =IF((Lecturas!V7-Lecturas!U7)<= 0,"",Lecturas!V7-Lecturas!U7) -> 0.265 | AQ9: =IFERROR(AP9*$AQ$3,"") -> 3.5306559 | AR9: =IF((Lecturas!W7-Lecturas!V7)<= 0,"",Lecturas!W7-Lecturas!V7) -> 1.305 | AS9: =IFERROR(AR9*$AS$3,"") -> 15.421089 | AT9: =IF((Lecturas!X7-Lecturas!W7)<= 0,"",Lecturas!X7-Lecturas!W7) -> 0.324 | AU9: =IFERROR(AT9*$AU$3,"") -> 3.8961625 | AV9: =IF((Lecturas!Y7-Lecturas!X7)<= 0,"",Lecturas!Y7-Lecturas!X7) -> 0.041 | AW9: =IFERROR(AV9*$AW$3,"") -> 0.50259656 | AX9: =IF((Lecturas!Z7-Lecturas!Y7)<= 0,"0",Lecturas!Z7-Lecturas!Y7) -> 2.764 | AY9: =IFERROR(AX9*$AY$3,"0") -> 32.073633 | AZ9: =IF((Lecturas!AA7-Lecturas!Z7)<= 0,"0",Lecturas!AA7-Lecturas!Z7) -> 4.434 | BA9: =IFERROR(AZ9*$BA$3,"0") -> 61.207072 | BB9: =IF((Lecturas!AB7-Lecturas!AA7)<= 0,"0",Lecturas!AB7-Lecturas!AA7) -> 5.065 | BC9: =IFERROR(BB9*$BC$3,"0") -> 75.902398 | BD9: =IF((Lecturas!AC7-Lecturas!AB7)<= 0,"0",Lecturas!AC7-Lecturas!AB7) -> 5.037 | BE9: =IFERROR(BD9*$BE$3,"0") -> 108.87484 | BF9: =IF((Lecturas!AD7-Lecturas!AC7)<= 0,"0",Lecturas!AD7-Lecturas!AC7) -> 0 | BG9: =IFERROR(BF9*$BG$3,"0") -> 0 | BH9: =IF((Lecturas!AE7-Lecturas!AD7)<= 0,"0",Lecturas!AE7-Lecturas!AD7) -> 0 | BI9: =IFERROR(BH9*$BI$3,"0") -> 0 | BJ9: =IF((Lecturas!AF7-Lecturas!AE7)<= 0,"0",Lecturas!AF7-Lecturas!AE7) -> 0 | BK9: =IFERROR(BJ9*$BK$3,"0") -> 0 | BL9: =IF((Lecturas!AG7-Lecturas!AF7)<= 0,"0",Lecturas!AG7-Lecturas!AF7) -> 0 | BM9: =IFERROR(BL9*$BM$3,"0") -> 0 | BN9: =IF((Lecturas!AH7-Lecturas!AG7)<= 0,"0",Lecturas!AH7-Lecturas!AG7) -> 0 | BO9: =IFERROR(BN9*$BO$3,"0") -> 0
A10: =ROUND(AG10,1) -> 47.3 | B10: =AF10 -> 3.319 | C10: 205 | D10: HILDA LUZ VELEZ GHERSI | E10: 2034039 | F10: =Lecturas!D8-Lecturas!C8 -> 2.259 | G10: =F10*$G$3 -> 50.45686 | H10: =IF((Lecturas!E8-Lecturas!D8) < 0, "", Lecturas!E8-Lecturas!D8) -> 2.372 | I10: =IFERROR(H10*$I$3,"") -> 42.377416 | J10: =IF(OR((Lecturas!F8-Lecturas!E8) <= 0), "", Lecturas!F8-Lecturas!E8) -> 2.51 | K10: =IFERROR(J10*$K$3,"") -> 30.523671 | L10: =IF(OR((Lecturas!G8-Lecturas!F8) <= 0), "", Lecturas!G8-Lecturas!F8) -> 2.102 | M10: =IFERROR(L10*$M$3,"") -> 32.813558 | N10: =IF(OR((Lecturas!H8-Lecturas!G8) <= 0), "", Lecturas!H8-Lecturas!G8) -> 1.776 | O10: =IFERROR(N10*$O$3,"") -> 26.98929 | P10: =IF(OR((Lecturas!I8-Lecturas!H8) < 0), "", Lecturas!I8-Lecturas!H8) -> 0 | Q10: =IFERROR(P10*$Q$3,"") -> 0 | R10: =IF(OR((Lecturas!J8-Lecturas!I8) <= 0), "", Lecturas!J8-Lecturas!I8) -> 0.665 | S10: =IFERROR(R10*$S$3,"") -> 11.020066 | T10: =IF(OR((Lecturas!K8-Lecturas!J8) <= 0), "", Lecturas!K8-Lecturas!J8) -> 1.254 | U10: =IFERROR(T10*$U$3,"") -> 22.022828 | V10: =IF(OR((Lecturas!L8-Lecturas!K8) <= 0), "", Lecturas!L8-Lecturas!K8) -> 1.722 | W10: =IFERROR(V10*$W$3,"") -> 21.048823 | X10: =IF(OR((Lecturas!M8-Lecturas!L8) < 0), "", Lecturas!M8-Lecturas!L8) -> 1.933 | Y10: =IFERROR(X10*$Y$3,"") -> 23.45575 | Z10: =IF(OR((Lecturas!N8-Lecturas!M8) <= 0), "", Lecturas!N8-Lecturas!M8) -> 1.437 | AA10: =IFERROR(Z10*$AA$3,"") -> 20.242044 | AB10: =IF(OR((Lecturas!O8-Lecturas!N8) < 0), "", Lecturas!O8-Lecturas!N8) -> 1.347 | AC10: =IFERROR(AB10*$AC$3,"") -> 17.304962 | AD10: =IF(OR((Lecturas!P8-Lecturas!O8) < 0), "", Lecturas!P8-Lecturas!O8) -> 1.576 | AE10: =IFERROR(AD10*$AE$3,"") -> 19.823222 | AF10: =IF((Lecturas!Q8-Lecturas!P8)<= 0,"",Lecturas!Q8-Lecturas!P8) -> 3.319 | AG10: =IFERROR(AF10*$AG$3,"") -> 47.288783 | AH10: =IF((Lecturas!R8-Lecturas!Q8)<= 0,"",Lecturas!R8-Lecturas!Q8) -> 0.33 | AI10: =IFERROR(AH10*$AI$3,"") -> 4.5916057 | AJ10: =IF((Lecturas!S8-Lecturas!R8)<= 0,"",Lecturas!S8-Lecturas!R8) -> 0.471 | AK10: =IFERROR(AJ10*$AK$3,"") -> 6.7860451 | AL10: =IF((Lecturas!T8-Lecturas!S8)<= 0,"",Lecturas!T8-Lecturas!S8) -> 0.602 | AM10: =IFERROR(AL10*$AM$3,"") -> 5.9771517 | AN10: =IF((Lecturas!U8-Lecturas!T8)<= 0,"",Lecturas!U8-Lecturas!T8) -> 0.558 | AO10: =IFERROR(AN10*$AO$3,"") -> 9.0747201 | AP10: =IF((Lecturas!V8-Lecturas!U8)<= 0,"",Lecturas!V8-Lecturas!U8) -> 2.052 | AQ10: =IFERROR(AP10*$AQ$3,"") -> 27.339268 | AR10: =IF((Lecturas!W8-Lecturas!V8)<= 0,"",Lecturas!W8-Lecturas!V8) -> 3.381 | AS10: =IFERROR(AR10*$AS$3,"") -> 39.953028 | AT10: =IF((Lecturas!X8-Lecturas!W8)<= 0,"",Lecturas!X8-Lecturas!W8) -> 4.006 | AU10: =IFERROR(AT10*$AU$3,"") -> 48.172922 | AV10: =IF((Lecturas!Y8-Lecturas!X8)<= 0,"",Lecturas!Y8-Lecturas!X8) | AW10: =IFERROR(AV10*$AW$3,"") -> 0 | AX10: =IF((Lecturas!Z8-Lecturas!Y8)<= 0,"0",Lecturas!Z8-Lecturas!Y8) -> 16.597 | AY10: =IFERROR(AX10*$AY$3,"0") -> 192.59265 | AZ10: =IF((Lecturas!AA8-Lecturas!Z8)<= 0,"0",Lecturas!AA8-Lecturas!Z8) -> 0.138 | BA10: =IFERROR(AZ10*$BA$3,"0") -> 1.9049562 | BB10: =IF((Lecturas!AB8-Lecturas!AA8)<= 0,"0",Lecturas!AB8-Lecturas!AA8) -> 0 | BC10: =IFERROR(BB10*$BC$3,"0") -> 0 | BD10: =IF((Lecturas!AC8-Lecturas!AB8)<= 0,"0",Lecturas!AC8-Lecturas!AB8) -> 0 | BE10: =IFERROR(BD10*$BE$3,"0") -> 0 | BF10: =IF((Lecturas!AD8-Lecturas!AC8)<= 0,"0",Lecturas!AD8-Lecturas!AC8) -> 0 | BG10: =IFERROR(BF10*$BG$3,"0") -> 0 | BH10: =IF((Lecturas!AE8-Lecturas!AD8)<= 0,"0",Lecturas!AE8-Lecturas!AD8) -> 0 | BI10: =IFERROR(BH10*$BI$3,"0") -> 0 | BJ10: =IF((Lecturas!AF8-Lecturas!AE8)<= 0,"0",Lecturas!AF8-Lecturas!AE8) -> 0 | BK10: =IFERROR(BJ10*$BK$3,"0") -> 0 | BL10: =IF((Lecturas!AG8-Lecturas!AF8)<= 0,"0",Lecturas!AG8-Lecturas!AF8) -> 0 | BM10: =IFERROR(BL10*$BM$3,"0") -> 0 | BN10: =IF((Lecturas!AH8-Lecturas!AG8)<= 0,"0",Lecturas!AH8-Lecturas!AG8) -> 0 | BO10: =IFERROR(BN10*$BO$3,"0") -> 0
A11: =ROUND(AG11,1) -> 192.8 | B11: =AF11 -> 13.533 | C11: 206 | D11: GUSTAVO ENRIQUE LOPEZ CORDERO | E11: 2034052 | F11: =Lecturas!D9-Lecturas!C9 -> 7.134 | G11: =F11*$G$3 -> 159.3445 | H11: =IF((Lecturas!E9-Lecturas!D9) < 0, "", Lecturas!E9-Lecturas!D9) -> 8.759 | I11: =IFERROR(H11*$I$3,"") -> 156.48557 | J11: =IF(OR((Lecturas!F9-Lecturas!E9) <= 0), "", Lecturas!F9-Lecturas!E9) -> 9.6 | K11: =IFERROR(J11*$K$3,"") -> 116.74392 | L11: =IF(OR((Lecturas!G9-Lecturas!F9) <= 0), "", Lecturas!G9-Lecturas!F9) -> 11.064 | M11: =IFERROR(L11*$M$3,"") -> 172.71608 | N11: =IF(OR((Lecturas!H9-Lecturas!G9) <= 0), "", Lecturas!H9-Lecturas!G9) -> 9.658 | O11: =IFERROR(N11*$O$3,"") -> 146.76946 | P11: =IF(OR((Lecturas!I9-Lecturas!H9) <= 0), "", Lecturas!I9-Lecturas!H9) -> 10.605 | Q11: =IFERROR(P11*$Q$3,"") -> 157.38824 | R11: =IF(OR((Lecturas!J9-Lecturas!I9) <= 0), "", Lecturas!J9-Lecturas!I9) -> 10.696 | S11: =IFERROR(R11*$S$3,"") -> 177.24906 | T11: =IF(OR((Lecturas!K9-Lecturas!J9) <= 0), "", Lecturas!K9-Lecturas!J9) -> 8.891 | U11: =IFERROR(T11*$U$3,"") -> 156.14431 | V11: =IF(OR((Lecturas!L9-Lecturas!K9) <= 0), "", Lecturas!L9-Lecturas!K9) -> 11.337 | W11: =IFERROR(V11*$W$3,"") -> 138.57753 | X11: =IF(OR((Lecturas!M9-Lecturas!L9) < 0), "", Lecturas!M9-Lecturas!L9) -> 11.777 | Y11: =IFERROR(X11*$Y$3,"") -> 142.90655 | Z11: =IF(OR((Lecturas!N9-Lecturas!M9) <= 0), "", Lecturas!N9-Lecturas!M9) -> 11.311 | AA11: =IFERROR(Z11*$AA$3,"") -> 159.33038 | AB11: =IF(OR((Lecturas!O9-Lecturas!N9) < 0), "", Lecturas!O9-Lecturas!N9) -> 11.237 | AC11: =IFERROR(AB11*$AC$3,"") -> 144.36218 | AD11: =IF(OR((Lecturas!P9-Lecturas!O9) < 0), "", Lecturas!P9-Lecturas!O9) -> 11.397 | AE11: =IFERROR(AD11*$AE$3,"") -> 143.35359 | AF11: =IF((Lecturas!Q9-Lecturas!P9)<= 0,"",Lecturas!Q9-Lecturas!P9) -> 13.533 | AG11: =IFERROR(AF11*$AG$3,"") -> 192.81684 | AH11: =IF((Lecturas!R9-Lecturas!Q9)<= 0,"",Lecturas!R9-Lecturas!Q9) -> 13.812 | AI11: =IFERROR(AH11*$AI$3,"") -> 192.17957 | AJ11: =IF((Lecturas!S9-Lecturas!R9)<= 0,"",Lecturas!S9-Lecturas!R9) -> 13.811 | AK11: =IFERROR(AJ11*$AK$3,"") -> 198.98528 | AL11: =IF((Lecturas!T9-Lecturas!S9)<= 0,"",Lecturas!T9-Lecturas!S9) -> 17.564 | AM11: =IFERROR(AL11*$AM$3,"") -> 174.38986 | AN11: =IF((Lecturas!U9-Lecturas!T9)<= 0,"",Lecturas!U9-Lecturas!T9) -> 11.868 | AO11: =IFERROR(AN11*$AO$3,"") -> 193.00856 | AP11: =IF((Lecturas!V9-Lecturas!U9)<= 0,"",Lecturas!V9-Lecturas!U9) -> 9.677 | AQ11: =IFERROR(AP11*$AQ$3,"") -> 128.9289 | AR11: =IF((Lecturas!W9-Lecturas!V9)<= 0,"",Lecturas!W9-Lecturas!V9) -> 15.338 | AS11: =IFERROR(AR11*$AS$3,"") -> 181.24802 | AT11: =IF((Lecturas!X9-Lecturas!W9)<= 0,"",Lecturas!X9-Lecturas!W9) -> 12.231 | AU11: =IFERROR(AT11*$AU$3,"") -> 147.08013 | AV11: =IF((Lecturas!Y9-Lecturas!X9)<= 0,"",Lecturas!Y9-Lecturas!X9) -> 12.779 | AW11: =IFERROR(AV11*$AW$3,"") -> 156.65077 | AX11: =IF((Lecturas!Z9-Lecturas!Y9)<= 0,"0",Lecturas!Z9-Lecturas!Y9) -> 12.467 | AY11: =IFERROR(AX11*$AY$3,"0") -> 144.66787 | AZ11: =IF((Lecturas!AA9-Lecturas!Z9)<= 0,"0",Lecturas!AA9-Lecturas!Z9) -> 13.319 | BA11: =IFERROR(AZ11*$BA$3,"0") -> 183.85589 | BB11: =IF((Lecturas!AB9-Lecturas!AA9)<= 0,"0",Lecturas!AB9-Lecturas!AA9) -> 12.028 | BC11: =IFERROR(BB11*$BC$3,"0") -> 180.24759 | BD11: =IF((Lecturas!AC9-Lecturas!AB9)<= 0,"0",Lecturas!AC9-Lecturas!AB9) -> 10.236 | BE11: =IFERROR(BD11*$BE$3,"0") -> 221.25132 | BF11: =IF((Lecturas!AD9-Lecturas!AC9)<= 0,"0",Lecturas!AD9-Lecturas!AC9) -> 0 | BG11: =IFERROR(BF11*$BG$3,"0") -> 0 | BH11: =IF((Lecturas!AE9-Lecturas!AD9)<= 0,"0",Lecturas!AE9-Lecturas!AD9) -> 0 | BI11: =IFERROR(BH11*$BI$3,"0") -> 0 | BJ11: =IF((Lecturas!AF9-Lecturas!AE9)<= 0,"0",Lecturas!AF9-Lecturas!AE9) -> 0 | BK11: =IFERROR(BJ11*$BK$3,"0") -> 0 | BL11: =IF((Lecturas!AG9-Lecturas!AF9)<= 0,"0",Lecturas!AG9-Lecturas!AF9) -> 0 | BM11: =IFERROR(BL11*$BM$3,"0") -> 0 | BN11: =IF((Lecturas!AH9-Lecturas!AG9)<= 0,"0",Lecturas!AH9-Lecturas!AG9) -> 0 | BO11: =IFERROR(BN11*$BO$3,"0") -> 0
A12: =ROUND(AG12,1) -> 0 | B12: =AF12 -> 0 | C12: 301 | D12: TRADEX INTERNACIONALSAC | E12: 2033964 | F12: =Lecturas!D10-Lecturas!C10 -> 0 | G12: =F12*$G$3 -> 0 | H12: =IF((Lecturas!E10-Lecturas!D10) < 0, "", Lecturas!E10-Lecturas!D10) -> 0 | I12: =IFERROR(H12*$I$3,"") -> 0 | J12: =IF(OR((Lecturas!F10-Lecturas!E10) < 0), "", Lecturas!F10-Lecturas!E10) -> 0 | K12: =IFERROR(J12*$K$3,"") -> 0 | L12: =IF(OR((Lecturas!G10-Lecturas!F10) < 0), "", Lecturas!G10-Lecturas!F10) -> 0 | M12: =IFERROR(L12*$M$3,"") -> 0 | N12: =IF(OR((Lecturas!H10-Lecturas!G10) < 0), "", Lecturas!H10-Lecturas!G10) -> 0 | O12: =IFERROR(N12*$O$3,"") -> 0 | P12: =IF(OR((Lecturas!I10-Lecturas!H10) < 0), "", Lecturas!I10-Lecturas!H10) -> 0 | Q12: =IFERROR(P12*$Q$3,"") -> 0 | R12: =IF(OR((Lecturas!J10-Lecturas!I10) < 0), "", Lecturas!J10-Lecturas!I10) -> 0 | S12: =IFERROR(R12*$S$3,"") -> 0 | T12: =IF(OR((Lecturas!K10-Lecturas!J10) < 0), "", Lecturas!K10-Lecturas!J10) -> 0 | U12: =IFERROR(T12*$U$3,"") -> 0 | V12: =IF(OR((Lecturas!L10-Lecturas!K10) < 0), "", Lecturas!L10-Lecturas!K10) -> 0 | W12: =IFERROR(V12*$W$3,"") -> 0 | X12: =IF(OR((Lecturas!M10-Lecturas!L10) < 0), "", Lecturas!M10-Lecturas!L10) -> 0 | Y12: =IFERROR(X12*$Y$3,"") -> 0 | Z12: =IF(OR((Lecturas!N10-Lecturas!M10) < 0), "", Lecturas!N10-Lecturas!M10) -> 0 | AA12: =IFERROR(Z12*$AA$3,"") -> 0 | AB12: =IF(OR((Lecturas!O10-Lecturas!N10) < 0), "", Lecturas!O10-Lecturas!N10) -> 0 | AC12: =IFERROR(AB12*$AC$3,"") -> 0 | AD12: =IF(OR((Lecturas!P10-Lecturas!O10) < 0), "", Lecturas!P10-Lecturas!O10) -> 0 | AE12: =IFERROR(AD12*$AE$3,"") -> 0 | AF12: =IF((Lecturas!Q10-Lecturas!P10)< 0,"",Lecturas!Q10-Lecturas!P10) -> 0 | AG12: =IFERROR(AF12*$AG$3,"") -> 0 | AH12: 0 | AI12: =IFERROR(AH12*$AI$3,"") -> 0 | AJ12: =IF((Lecturas!S10-Lecturas!R10)<= 0,"",Lecturas!S10-Lecturas!R10) | AK12: =IFERROR(AJ12*$AK$3,"") -> 0 | AL12: =IF((Lecturas!T10-Lecturas!S10)<= 0,"",Lecturas!T10-Lecturas!S10) | AM12: =IFERROR(AL12*$AM$3,"") -> 0 | AN12: =IF((Lecturas!U10-Lecturas!T10)<= 0,"",Lecturas!U10-Lecturas!T10) | AO12: =IFERROR(AN12*$AO$3,"") -> 0 | AP12: =IF((Lecturas!V10-Lecturas!U10)<= 0,"",Lecturas!V10-Lecturas!U10) | AQ12: =IFERROR(AP12*$AQ$3,"") -> 0 | AR12: =IF((Lecturas!W10-Lecturas!V10)<= 0,"",Lecturas!W10-Lecturas!V10) | AS12: =IFERROR(AR12*$AS$3,"") -> 0 | AT12: =IF((Lecturas!X10-Lecturas!W10)<= 0,"",Lecturas!X10-Lecturas!W10) | AU12: =IFERROR(AT12*$AU$3,"") -> 0 | AV12: =IF((Lecturas!Y10-Lecturas!X10)<= 0,"",Lecturas!Y10-Lecturas!X10) | AW12: =IFERROR(AV12*$AW$3,"") -> 0 | AX12: =IF((Lecturas!Z10-Lecturas!Y10)<= 0,"0",Lecturas!Z10-Lecturas!Y10) -> 0 | AY12: =IFERROR(AX12*$AY$3,"0") -> 0 | AZ12: =IF((Lecturas!AA10-Lecturas!Z10)<= 0,"0",Lecturas!AA10-Lecturas!Z10) -> 0 | BA12: =IFERROR(AZ12*$BA$3,"0") -> 0 | BB12: =IF((Lecturas!AB10-Lecturas!AA10)<= 0,"0",Lecturas!AB10-Lecturas!AA10) -> 0 | BC12: =IFERROR(BB12*$BC$3,"0") -> 0 | BD12: =IF((Lecturas!AC10-Lecturas!AB10)<= 0,"0",Lecturas!AC10-Lecturas!AB10) -> 0 | BE12: =IFERROR(BD12*$BE$3,"0") -> 0 | BF12: =IF((Lecturas!AD10-Lecturas!AC10)<= 0,"0",Lecturas!AD10-Lecturas!AC10) -> 0 | BG12: =IFERROR(BF12*$BG$3,"0") -> 0 | BH12: =IF((Lecturas!AE10-Lecturas!AD10)<= 0,"0",Lecturas!AE10-Lecturas!AD10) -> 0 | BI12: =IFERROR(BH12*$BI$3,"0") -> 0 | BJ12: =IF((Lecturas!AF10-Lecturas!AE10)<= 0,"0",Lecturas!AF10-Lecturas!AE10) -> 0 | BK12: =IFERROR(BJ12*$BK$3,"0") -> 0 | BL12: =IF((Lecturas!AG10-Lecturas!AF10)<= 0,"0",Lecturas!AG10-Lecturas!AF10) -> 0 | BM12: =IFERROR(BL12*$BM$3,"0") -> 0 | BN12: =IF((Lecturas!AH10-Lecturas!AG10)<= 0,"0",Lecturas!AH10-Lecturas!AG10) -> 0 | BO12: =IFERROR(BN12*$BO$3,"0") -> 0
A13: =ROUND(AG13,1) -> 0 | B13: =AF13 -> 0 | C13: 301 | D13: ORELLANA HOLDAN OSCAR BRUNO | E13: GA170801166 | F13: =Lecturas!D11-Lecturas!C11 -> 0 | G13: =F13*$G$3 -> 0 | H13: =IF((Lecturas!E11-Lecturas!D11) < 0, "", Lecturas!E11-Lecturas!D11) -> 0 | I13: =IFERROR(H13*$I$3,"") -> 0 | J13: =IF(OR((Lecturas!F11-Lecturas!E11) < 0), "", Lecturas!F11-Lecturas!E11) -> 0 | K13: =IFERROR(J13*$K$3,"") -> 0 | L13: =IF(OR((Lecturas!G11-Lecturas!F11) < 0), "", Lecturas!G11-Lecturas!F11) -> 0 | M13: =IFERROR(L13*$M$3,"") -> 0 | N13: =IF(OR((Lecturas!H11-Lecturas!G11) < 0), "", Lecturas!H11-Lecturas!G11) -> 0 | O13: =IFERROR(N13*$O$3,"") -> 0 | P13: =IF(OR((Lecturas!I11-Lecturas!H11) < 0), "", Lecturas!I11-Lecturas!H11) -> 0 | Q13: =IFERROR(P13*$Q$3,"") -> 0 | R13: =IF(OR((Lecturas!J11-Lecturas!I11) < 0), "", Lecturas!J11-Lecturas!I11) -> 0 | S13: =IFERROR(R13*$S$3,"") -> 0 | T13: =IF(OR((Lecturas!K11-Lecturas!J11) < 0), "", Lecturas!K11-Lecturas!J11) -> 0 | U13: =IFERROR(T13*$U$3,"") -> 0 | V13: =IF(OR((Lecturas!L11-Lecturas!K11) < 0), "", Lecturas!L11-Lecturas!K11) -> 0 | W13: =IFERROR(V13*$W$3,"") -> 0 | X13: =IF(OR((Lecturas!M11-Lecturas!L11) < 0), "", Lecturas!M11-Lecturas!L11) -> 0 | Y13: =IFERROR(X13*$Y$3,"") -> 0 | Z13: =IF(OR((Lecturas!N11-Lecturas!M11) < 0), "", Lecturas!N11-Lecturas!M11) -> 0 | AA13: =IFERROR(Z13*$AA$3,"") -> 0 | AB13: =IF(OR((Lecturas!O11-Lecturas!N11) < 0), "", Lecturas!O11-Lecturas!N11) -> 0 | AC13: =IFERROR(AB13*$AC$3,"") -> 0 | AD13: =IF(OR((Lecturas!P11-Lecturas!O11) < 0), "", Lecturas!P11-Lecturas!O11) -> 0 | AE13: =IFERROR(AD13*$AE$3,"") -> 0 | AF13: =IF((Lecturas!Q11-Lecturas!P11)< 0,"",Lecturas!Q11-Lecturas!P11) -> 0 | AG13: =IFERROR(AF13*$AG$3,"") -> 0 | AH13: 0 | AI13: =IFERROR(AH13*$AI$3,"") -> 0 | AJ13: =IF((Lecturas!S11-Lecturas!R11)<= 0,"",Lecturas!S11-Lecturas!R11) | AK13: =IFERROR(AJ13*$AK$3,"") -> 0 | AL13: =IF((Lecturas!T11-Lecturas!S11)<= 0,"",Lecturas!T11-Lecturas!S11) | AM13: =IFERROR(AL13*$AM$3,"") -> 0 | AN13: =IF((Lecturas!U11-Lecturas!T11)<= 0,"",Lecturas!U11-Lecturas!T11) | AO13: =IFERROR(AN13*$AO$3,"") -> 0 | AP13: =IF((Lecturas!V11-Lecturas!U11)<= 0,"",Lecturas!V11-Lecturas!U11) | AQ13: =IFERROR(AP13*$AQ$3,"") -> 0 | AR13: =IF((Lecturas!W11-Lecturas!V11)<= 0,"",Lecturas!W11-Lecturas!V11) | AS13: =IFERROR(AR13*$AS$3,"") -> 0 | AT13: =IF((Lecturas!X11-Lecturas!W11)<= 0,"",Lecturas!X11-Lecturas!W11) | AU13: =IFERROR(AT13*$AU$3,"") -> 0 | AV13: =IF((Lecturas!Y11-Lecturas!X11)<= 0,"",Lecturas!Y11-Lecturas!X11) | AW13: =IFERROR(AV13*$AW$3,"") -> 0 | AX13: =IF((Lecturas!Z11-Lecturas!Y11)<= 0,"0",Lecturas!Z11-Lecturas!Y11) -> 0 | AY13: =IFERROR(AX13*$AY$3,"0") -> 0 | AZ13: =IF((Lecturas!AA11-Lecturas!Z11)<= 0,"0",Lecturas!AA11-Lecturas!Z11) -> 0 | BA13: =IFERROR(AZ13*$BA$3,"0") -> 0 | BB13: =IF((Lecturas!AB11-Lecturas!AA11)<= 0,"0",Lecturas!AB11-Lecturas!AA11) -> 0 | BC13: =IFERROR(BB13*$BC$3,"0") -> 0 | BD13: =IF((Lecturas!AC11-Lecturas!AB11)<= 0,"0",Lecturas!AC11-Lecturas!AB11) -> 0 | BE13: =IFERROR(BD13*$BE$3,"0") -> 0 | BF13: =IF((Lecturas!AD11-Lecturas!AC11)<= 0,"0",Lecturas!AD11-Lecturas!AC11) -> 0 | BG13: =IFERROR(BF13*$BG$3,"0") -> 0 | BH13: =IF((Lecturas!AE11-Lecturas!AD11)<= 0,"0",Lecturas!AE11-Lecturas!AD11) -> 0 | BI13: =IFERROR(BH13*$BI$3,"0") -> 0 | BJ13: =IF((Lecturas!AF11-Lecturas!AE11)<= 0,"0",Lecturas!AF11-Lecturas!AE11) -> 0 | BK13: =IFERROR(BJ13*$BK$3,"0") -> 0 | BL13: =IF((Lecturas!AG11-Lecturas!AF11)<= 0,"0",Lecturas!AG11-Lecturas!AF11) -> 0 | BM13: =IFERROR(BL13*$BM$3,"0") -> 0 | BN13: =IF((Lecturas!AH11-Lecturas!AG11)<= 0,"0",Lecturas!AH11-Lecturas!AG11) -> 0 | BO13: =IFERROR(BN13*$BO$3,"0") -> 0
A14: =ROUND(AG14,1) -> 11.6 | B14: =AF14 -> 0.817 | C14: 302 | D14: MARGOT MEDINA CARDENAS | E14: 2034062 | F14: =Lecturas!D12-Lecturas!C12 -> 4.871 | G14: =F14*$G$3 -> 108.7983 | H14: =IF((Lecturas!E12-Lecturas!D12) < 0, "", Lecturas!E12-Lecturas!D12) -> 1.266 | I14: =IFERROR(H14*$I$3,"") -> 22.617963 | J14: =IF(OR((Lecturas!F12-Lecturas!E12) <= 0), "", Lecturas!F12-Lecturas!E12) -> 0.499 | K14: =IFERROR(J14*$K$3,"") -> 6.0682517 | L14: =IF(OR((Lecturas!G12-Lecturas!F12) <= 0), "", Lecturas!G12-Lecturas!F12) -> 0.945 | M14: =IFERROR(L14*$M$3,"") -> 14.752052 | N14: =IF(OR((Lecturas!H12-Lecturas!G12) <= 0), "", Lecturas!H12-Lecturas!G12) -> 0.693 | O14: =IFERROR(N14*$O$3,"") -> 10.531294 | P14: =IF(OR((Lecturas!I12-Lecturas!H12) <= 0), "", Lecturas!I12-Lecturas!H12) -> 0.849 | Q14: =IFERROR(P14*$Q$3,"") -> 12.599964 | R14: =IF(OR((Lecturas!J12-Lecturas!I12) <= 0), "", Lecturas!J12-Lecturas!I12) -> 1.12 | S14: =IFERROR(R14*$S$3,"") -> 18.560111 | T14: =IF(OR((Lecturas!K12-Lecturas!J12) <= 0), "", Lecturas!K12-Lecturas!J12) -> 2.602 | U14: =IFERROR(T14*$U$3,"") -> 45.69649 | V14: =IF(OR((Lecturas!L12-Lecturas!K12) < 0), "", Lecturas!L12-Lecturas!K12) -> 3.413 | W14: =IFERROR(V14*$W$3,"") -> 41.718718 | X14: =IF(OR((Lecturas!M12-Lecturas!L12) < 0), "", Lecturas!M12-Lecturas!L12) -> 2.994 | Y14: =IFERROR(X14*$Y$3,"") -> 36.330323 | Z14: =IF(OR((Lecturas!N12-Lecturas!M12) <= 0), "", Lecturas!N12-Lecturas!M12) -> 0.795 | AA14: =IFERROR(Z14*$AA$3,"") -> 11.198626 | AB14: =IF(OR((Lecturas!O12-Lecturas!N12) < 0), "", Lecturas!O12-Lecturas!N12) -> 2.54 | AC14: =IFERROR(AB14*$AC$3,"") -> 32.631479 | AD14: =IF(OR((Lecturas!P12-Lecturas!O12) < 0), "", Lecturas!P12-Lecturas!O12) -> 2.333 | AE14: =IFERROR(AD14*$AE$3,"") -> 29.344909 | AF14: =IF((Lecturas!Q12-Lecturas!P12)<= 0,"",Lecturas!Q12-Lecturas!P12) -> 0.817 | AG14: =IFERROR(AF14*$AG$3,"") -> 11.640535 | AH14: =IF((Lecturas!R12-Lecturas!Q12)<= 0,"",Lecturas!R12-Lecturas!Q12) -> 3.466 | AI14: =IFERROR(AH14*$AI$3,"") -> 48.225774 | AJ14: =IF((Lecturas!S12-Lecturas!R12)<= 0,"",Lecturas!S12-Lecturas!R12) -> 4.252 | AK14: =IFERROR(AJ14*$AK$3,"") -> 61.261706 | AL14: =IF((Lecturas!T12-Lecturas!S12)<= 0,"",Lecturas!T12-Lecturas!S12) -> 4.214 | AM14: =IFERROR(AL14*$AM$3,"") -> 41.840062 | AN14: =IF((Lecturas!U12-Lecturas!T12)<= 0,"",Lecturas!U12-Lecturas!T12) -> 2.682 | AO14: =IFERROR(AN14*$AO$3,"") -> 43.617203 | AP14: =IF((Lecturas!V12-Lecturas!U12)<= 0,"",Lecturas!V12-Lecturas!U12) -> 3.858 | AQ14: =IFERROR(AP14*$AQ$3,"") -> 51.401021 | AR14: =IF((Lecturas!W12-Lecturas!V12)<= 0,"",Lecturas!W12-Lecturas!V12) -> 3.688 | AS14: =IFERROR(AR14*$AS$3,"") -> 43.580824 | AT14: =IF((Lecturas!X12-Lecturas!W12)<= 0,"",Lecturas!X12-Lecturas!W12) -> 2.838 | AU14: =IFERROR(AT14*$AU$3,"") -> 34.127497 | AV14: =IF((Lecturas!Y12-Lecturas!X12)<= 0,"",Lecturas!Y12-Lecturas!X12) -> 3.403 | AW14: =IFERROR(AV14*$AW$3,"") -> 41.715515 | AX14: =IF((Lecturas!Z12-Lecturas!Y12)<= 0,"0",Lecturas!Z12-Lecturas!Y12) -> 3.216 | AY14: =IFERROR(AX14*$AY$3,"0") -> 37.31867 | AZ14: =IF((Lecturas!AA12-Lecturas!Z12)<= 0,"0",Lecturas!AA12-Lecturas!Z12) -> 4.148 | BA14: =IFERROR(AZ14*$BA$3,"0") -> 57.25912 | BB14: =IF((Lecturas!AB12-Lecturas!AA12)<= 0,"0",Lecturas!AB12-Lecturas!AA12) -> 3.923 | BC14: =IFERROR(BB14*$BC$3,"0") -> 58.788767 | BD14: =IF((Lecturas!AC12-Lecturas!AB12)<= 0,"0",Lecturas!AC12-Lecturas!AB12) -> 4.07 | BE14: =IFERROR(BD14*$BE$3,"0") -> 87.973122 | BF14: =IF((Lecturas!AD12-Lecturas!AC12)<= 0,"0",Lecturas!AD12-Lecturas!AC12) -> 0 | BG14: =IFERROR(BF14*$BG$3,"0") -> 0 | BH14: =IF((Lecturas!AE12-Lecturas!AD12)<= 0,"0",Lecturas!AE12-Lecturas!AD12) -> 0 | BI14: =IFERROR(BH14*$BI$3,"0") -> 0 | BJ14: =IF((Lecturas!AF12-Lecturas!AE12)<= 0,"0",Lecturas!AF12-Lecturas!AE12) -> 0 | BK14: =IFERROR(BJ14*$BK$3,"0") -> 0 | BL14: =IF((Lecturas!AG12-Lecturas!AF12)<= 0,"0",Lecturas!AG12-Lecturas!AF12) -> 0 | BM14: =IFERROR(BL14*$BM$3,"0") -> 0 | BN14: =IF((Lecturas!AH12-Lecturas!AG12)<= 0,"0",Lecturas!AH12-Lecturas!AG12) -> 0 | BO14: =IFERROR(BN14*$BO$3,"0") -> 0
A15: =ROUND(AG15,1) -> 26.2 | B15: =AF15 -> 1.84 | C15: 303 | D15: OSCAR MARIMON PACHECO | E15: 2034065 | F15: =Lecturas!D13-Lecturas!C13 -> 1.486 | G15: =F15*$G$3 -> 33.191188 | H15: =IF((Lecturas!E13-Lecturas!D13) < 0, "", Lecturas!E13-Lecturas!D13) -> 1.629 | I15: =IFERROR(H15*$I$3,"") -> 29.103208 | J15: =IF(OR((Lecturas!F13-Lecturas!E13) <= 0), "", Lecturas!F13-Lecturas!E13) -> 2.991 | K15: =IFERROR(J15*$K$3,"") -> 36.373027 | L15: =IF(OR((Lecturas!G13-Lecturas!F13) <= 0), "", Lecturas!G13-Lecturas!F13) -> 1.42 | M15: =IFERROR(L15*$M$3,"") -> 22.167104 | N15: =IF(OR((Lecturas!H13-Lecturas!G13) <= 0), "", Lecturas!H13-Lecturas!G13) -> 2.517 | O15: =IFERROR(N15*$O$3,"") -> 38.250024 | P15: =IF(OR((Lecturas!I13-Lecturas!H13) <= 0), "", Lecturas!I13-Lecturas!H13) -> 1.461 | Q15: =IFERROR(P15*$Q$3,"") -> 21.682623 | R15: =IF(OR((Lecturas!J13-Lecturas!I13) <= 0), "", Lecturas!J13-Lecturas!I13) -> 4.412 | S15: =IFERROR(R15*$S$3,"") -> 73.11358 | T15: =IF(OR((Lecturas!K13-Lecturas!J13) <= 0), "", Lecturas!K13-Lecturas!J13) -> 1.043 | U15: =IFERROR(T15*$U$3,"") -> 18.317233 | V15: =IF(OR((Lecturas!L13-Lecturas!K13) < 0), "", Lecturas!L13-Lecturas!K13) -> 3.333 | W15: =IFERROR(V15*$W$3,"") -> 40.74084 | X15: =IF(OR((Lecturas!M13-Lecturas!L13) < 0), "", Lecturas!M13-Lecturas!L13) -> 6.026 | Y15: =IFERROR(X15*$Y$3,"") -> 73.121752 | Z15: =IF(OR((Lecturas!N13-Lecturas!M13) <= 0), "", Lecturas!N13-Lecturas!M13) -> 7.826 | AA15: =IFERROR(Z15*$AA$3,"") -> 110.23955 | AB15: =IF(OR((Lecturas!O13-Lecturas!N13) < 0), "", Lecturas!O13-Lecturas!N13) -> 5.635 | AC15: =IFERROR(AB15*$AC$3,"") -> 72.393065 | AD15: =IF(OR((Lecturas!P13-Lecturas!O13) < 0), "", Lecturas!P13-Lecturas!O13) -> 6.073 | AE15: =IFERROR(AD15*$AE$3,"") -> 76.387326 | AF15: =IF((Lecturas!Q13-Lecturas!P13)<= 0,"",Lecturas!Q13-Lecturas!P13) -> 1.84 | AG15: =IFERROR(AF15*$AG$3,"") -> 26.216137 | AH15: =IF((Lecturas!R13-Lecturas!Q13)<= 0,"",Lecturas!R13-Lecturas!Q13) -> 4.793 | AI15: =IFERROR(AH15*$AI$3,"") -> 66.689594 | AJ15: =IF((Lecturas!S13-Lecturas!R13)<= 0,"",Lecturas!S13-Lecturas!R13) -> 4.294 | AK15: =IFERROR(AJ15*$AK$3,"") -> 61.866831 | AL15: =IF((Lecturas!T13-Lecturas!S13)<= 0,"",Lecturas!T13-Lecturas!S13) -> 2.082 | AM15: =IFERROR(AL15*$AM$3,"") -> 20.671811 | AN15: =IF((Lecturas!U13-Lecturas!T13)<= 0,"",Lecturas!U13-Lecturas!T13) -> 1.297 | AO15: =IFERROR(AN15*$AO$3,"") -> 21.093032 | AP15: =IF((Lecturas!V13-Lecturas!U13)<= 0,"",Lecturas!V13-Lecturas!U13) -> 1.004 | AQ15: =IFERROR(AP15*$AQ$3,"") -> 13.376523 | AR15: =IF((Lecturas!W13-Lecturas!V13)<= 0,"",Lecturas!W13-Lecturas!V13) -> 3.375 | AS15: =IFERROR(AR15*$AS$3,"") -> 39.882126 | AT15: =IF((Lecturas!X13-Lecturas!W13)<= 0,"",Lecturas!X13-Lecturas!W13) -> 5.197 | AU15: =IFERROR(AT15*$AU$3,"") -> 62.494927 | AV15: =IF((Lecturas!Y13-Lecturas!X13)<= 0,"",Lecturas!Y13-Lecturas!X13) -> 0.987 | AW15: =IFERROR(AV15*$AW$3,"") -> 12.099093 | AX15: =IF((Lecturas!Z13-Lecturas!Y13)<= 0,"0",Lecturas!Z13-Lecturas!Y13) -> 2.951 | AY15: =IFERROR(AX15*$AY$3,"0") -> 34.243593 | AZ15: =IF((Lecturas!AA13-Lecturas!Z13)<= 0,"0",Lecturas!AA13-Lecturas!Z13) -> 1.35 | BA15: =IFERROR(AZ15*$BA$3,"0") -> 18.635442 | BB15: =IF((Lecturas!AB13-Lecturas!AA13)<= 0,"0",Lecturas!AB13-Lecturas!AA13) -> 4.076 | BC15: =IFERROR(BB15*$BC$3,"0") -> 61.081574 | BD15: =IF((Lecturas!AC13-Lecturas!AB13)<= 0,"0",Lecturas!AC13-Lecturas!AB13) -> 3.287 | BE15: =IFERROR(BD15*$BE$3,"0") -> 71.048563 | BF15: =IF((Lecturas!AD13-Lecturas!AC13)<= 0,"0",Lecturas!AD13-Lecturas!AC13) -> 0 | BG15: =IFERROR(BF15*$BG$3,"0") -> 0 | BH15: =IF((Lecturas!AE13-Lecturas!AD13)<= 0,"0",Lecturas!AE13-Lecturas!AD13) -> 0 | BI15: =IFERROR(BH15*$BI$3,"0") -> 0 | BJ15: =IF((Lecturas!AF13-Lecturas!AE13)<= 0,"0",Lecturas!AF13-Lecturas!AE13) -> 0 | BK15: =IFERROR(BJ15*$BK$3,"0") -> 0 | BL15: =IF((Lecturas!AG13-Lecturas!AF13)<= 0,"0",Lecturas!AG13-Lecturas!AF13) -> 0 | BM15: =IFERROR(BL15*$BM$3,"0") -> 0 | BN15: =IF((Lecturas!AH13-Lecturas!AG13)<= 0,"0",Lecturas!AH13-Lecturas!AG13) -> 0 | BO15: =IFERROR(BN15*$BO$3,"0") -> 0
A16: =ROUND(AG16,1) -> 29.8 | B16: =AF16 -> 2.09 | C16: 304 | D16: VICTORIA CARLOTA FEBRES ORE | E16: 2034043 | F16: =Lecturas!D14-Lecturas!C14 -> 0.616 | G16: =F16*$G$3 -> 13.758931 | H16: =IF((Lecturas!E14-Lecturas!D14) < 0, "", Lecturas!E14-Lecturas!D14) -> 0.611 | I16: =IFERROR(H16*$I$3,"") -> 10.915936 | J16: =IF(OR((Lecturas!F14-Lecturas!E14) < 0), "", Lecturas!F14-Lecturas!E14) -> 0 | K16: =IFERROR(J16*$K$3,"") -> 0 | L16: =IF(OR((Lecturas!G14-Lecturas!F14) <= 0), "", Lecturas!G14-Lecturas!F14) -> 4.376 | M16: =IFERROR(L16*$M$3,"") -> 68.312146 | N16: =IF(OR((Lecturas!H14-Lecturas!G14) <= 0), "", Lecturas!H14-Lecturas!G14) -> 3.587 | O16: =IFERROR(N16*$O$3,"") -> 54.510463 | P16: =IF(OR((Lecturas!I14-Lecturas!H14) <= 0), "", Lecturas!I14-Lecturas!H14) -> 2.449 | Q16: =IFERROR(P16*$Q$3,"") -> 36.345479 | R16: =IF(OR((Lecturas!J14-Lecturas!I14) <= 0), "", Lecturas!J14-Lecturas!I14) -> 1.184 | S16: =IFERROR(R16*$S$3,"") -> 19.620689 | T16: =IF(OR((Lecturas!K14-Lecturas!J14) <= 0), "", Lecturas!K14-Lecturas!J14) -> 0.002 | U16: =IFERROR(T16*$U$3,"") -> 0.035124128 | V16: =IF(OR((Lecturas!L14-Lecturas!K14) < 0), "", Lecturas!L14-Lecturas!K14) -> 0.062 | W16: =IFERROR(V16*$W$3,"") -> 0.75785541 | X16: =IF(OR((Lecturas!M14-Lecturas!L14) < 0), "", Lecturas!M14-Lecturas!L14) -> 0 | Y16: =IFERROR(X16*$Y$3,"") -> 0 | Z16: =IF(OR((Lecturas!N14-Lecturas!M14) <= 0), "", Lecturas!N14-Lecturas!M14) -> 5.724 | AA16: =IFERROR(Z16*$AA$3,"") -> 80.630105 | AB16: =IF(OR((Lecturas!O14-Lecturas!N14) < 0), "", Lecturas!O14-Lecturas!N14) -> 3.688 | AC16: =IFERROR(AB16*$AC$3,"") -> 47.37988 | AD16: =IF(OR((Lecturas!P14-Lecturas!O14) < 0), "", Lecturas!P14-Lecturas!O14) -> 4.763 | AE16: =IFERROR(AD16*$AE$3,"") -> 59.909902 | AF16: =IF((Lecturas!Q14-Lecturas!P14)<= 0,"",Lecturas!Q14-Lecturas!P14) -> 2.09 | AG16: =IFERROR(AF16*$AG$3,"") -> 29.778113 | AH16: =IF((Lecturas!R14-Lecturas!Q14)<= 0,"",Lecturas!R14-Lecturas!Q14) -> 0.006 | AI16: =IFERROR(AH16*$AI$3,"") -> 0.08348374 | AJ16: =IF((Lecturas!S14-Lecturas!R14)<= 0,"",Lecturas!S14-Lecturas!R14) -> 0.005 | AK16: =IFERROR(AJ16*$AK$3,"") -> 0.072038695 | AL16: =IF((Lecturas!T14-Lecturas!S14)<= 0,"",Lecturas!T14-Lecturas!S14) -> 0.002 | AM16: =IFERROR(AL16*$AM$3,"") -> 0.019857647 | AN16: =IF((Lecturas!U14-Lecturas!T14)<= 0,"",Lecturas!U14-Lecturas!T14) -> 2.289 | AO16: =IFERROR(AN16*$AO$3,"") -> 37.225868 | AP16: =IF((Lecturas!V14-Lecturas!U14)<= 0,"",Lecturas!V14-Lecturas!U14) -> 0.102 | AQ16: =IFERROR(AP16*$AQ$3,"") -> 1.3589694 | AR16: =IF((Lecturas!W14-Lecturas!V14)<= 0,"",Lecturas!W14-Lecturas!V14) -> 2.171 | AS16: =IFERROR(AR16*$AS$3,"") -> 25.654547 | AT16: =IF((Lecturas!X14-Lecturas!W14)<= 0,"",Lecturas!X14-Lecturas!W14) -> 0.001 | AU16: =IFERROR(AT16*$AU$3,"") -> 0.012025193 | AV16: =IF((Lecturas!Y14-Lecturas!X14)<= 0,"",Lecturas!Y14-Lecturas!X14) -> 2.248 | AW16: =IFERROR(AV16*$AW$3,"") -> 27.557002 | AX16: =IF((Lecturas!Z14-Lecturas!Y14)<= 0,"0",Lecturas!Z14-Lecturas!Y14) -> 4.133 | AY16: =IFERROR(AX16*$AY$3,"0") -> 47.959597 | AZ16: =IF((Lecturas!AA14-Lecturas!Z14)<= 0,"0",Lecturas!AA14-Lecturas!Z14) -> 4.615 | BA16: =IFERROR(AZ16*$BA$3,"0") -> 63.705602 | BB16: =IF((Lecturas!AB14-Lecturas!AA14)<= 0,"0",Lecturas!AB14-Lecturas!AA14) -> 3.989 | BC16: =IFERROR(BB16*$BC$3,"0") -> 59.777821 | BD16: =IF((Lecturas!AC14-Lecturas!AB14)<= 0,"0",Lecturas!AC14-Lecturas!AB14) -> 2.001 | BE16: =IFERROR(BD16*$BE$3,"0") -> 43.25165 | BF16: =IF((Lecturas!AD14-Lecturas!AC14)<= 0,"0",Lecturas!AD14-Lecturas!AC14) -> 0 | BG16: =IFERROR(BF16*$BG$3,"0") -> 0 | BH16: =IF((Lecturas!AE14-Lecturas!AD14)<= 0,"0",Lecturas!AE14-Lecturas!AD14) -> 0 | BI16: =IFERROR(BH16*$BI$3,"0") -> 0 | BJ16: =IF((Lecturas!AF14-Lecturas!AE14)<= 0,"0",Lecturas!AF14-Lecturas!AE14) -> 0 | BK16: =IFERROR(BJ16*$BK$3,"0") -> 0 | BL16: =IF((Lecturas!AG14-Lecturas!AF14)<= 0,"0",Lecturas!AG14-Lecturas!AF14) -> 0 | BM16: =IFERROR(BL16*$BM$3,"0") -> 0 | BN16: =IF((Lecturas!AH14-Lecturas!AG14)<= 0,"0",Lecturas!AH14-Lecturas!AG14) -> 0 | BO16: =IFERROR(BN16*$BO$3,"0") -> 0
A17: =ROUND(AG17,1) -> 0 | B17: =AF17 -> 0 | C17: 305 | D17: ROSA MARIA MONTENEGRO TORIBIO | E17: 2034044 | F17: =Lecturas!D15-Lecturas!C15 -> 1.522 | G17: =F17*$G$3 -> 33.995281 | H17: =IF((Lecturas!E15-Lecturas!D15) < 0, "", Lecturas!E15-Lecturas!D15) -> 1.541 | I17: =IFERROR(H17*$I$3,"") -> 27.531028 | J17: =IF(OR((Lecturas!F15-Lecturas!E15) <= 0), "", Lecturas!F15-Lecturas!E15) -> 1.523 | K17: =IFERROR(J17*$K$3,"") -> 18.520936 | L17: =IF(OR((Lecturas!G15-Lecturas!F15) <= 0), "", Lecturas!G15-Lecturas!F15) -> 1.312 | M17: =IFERROR(L17*$M$3,"") -> 20.481155 | N17: =IF(OR((Lecturas!H15-Lecturas!G15) <= 0), "", Lecturas!H15-Lecturas!G15) -> 1.465 | O17: =IFERROR(N17*$O$3,"") -> 22.263125 | P17: =IF(OR((Lecturas!I15-Lecturas!H15) <= 0), "", Lecturas!I15-Lecturas!H15) -> 1.355 | Q17: =IFERROR(P17*$Q$3,"") -> 20.109483 | R17: =IF(OR((Lecturas!J15-Lecturas!I15) <= 0), "", Lecturas!J15-Lecturas!I15) -> 1.184 | S17: =IFERROR(R17*$S$3,"") -> 19.620689 | T17: =IF(OR((Lecturas!K15-Lecturas!J15) <= 0), "", Lecturas!K15-Lecturas!J15) -> 0.251 | U17: =IFERROR(T17*$U$3,"") -> 4.408078 | V17: =IF(OR((Lecturas!L15-Lecturas!K15) < 0), "", Lecturas!L15-Lecturas!K15) -> 0.45 | W17: =IFERROR(V17*$W$3,"") -> 5.5005635 | X17: =IF(OR((Lecturas!M15-Lecturas!L15) < 0), "", Lecturas!M15-Lecturas!L15) -> 0 | Y17: =IFERROR(X17*$Y$3,"") -> 0 | Z17: =IF(OR((Lecturas!N15-Lecturas!M15) <= 0), "", Lecturas!N15-Lecturas!M15) -> 0.386 | AA17: =IFERROR(Z17*$AA$3,"") -> 5.4373202 | AB17: =IF(OR((Lecturas!O15-Lecturas!N15) < 0), "", Lecturas!O15-Lecturas!N15) -> 0 | AC17: =IFERROR(AB17*$AC$3,"") -> 0 | AD17: =IF(OR((Lecturas!P15-Lecturas!O15) < 0), "", Lecturas!P15-Lecturas!O15) -> 0 | AE17: =IFERROR(AD17*$AE$3,"") -> 0 | AF17: =IF((Lecturas!Q15-Lecturas!P15)< 0,"",Lecturas!Q15-Lecturas!P15) -> 0 | AG17: =IFERROR(AF17*$AG$3,"") -> 0 | AH17: 0 | AI17: =IFERROR(AH17*$AI$3,"") -> 0 | AJ17: =IF((Lecturas!S15-Lecturas!R15)<= 0,"",Lecturas!S15-Lecturas!R15) | AK17: =IFERROR(AJ17*$AK$3,"") -> 0 | AL17: =IF((Lecturas!T15-Lecturas!S15)<= 0,"",Lecturas!T15-Lecturas!S15) | AM17: =IFERROR(AL17*$AM$3,"") -> 0 | AN17: =IF((Lecturas!U15-Lecturas!T15)<= 0,"",Lecturas!U15-Lecturas!T15) | AO17: =IFERROR(AN17*$AO$3,"") -> 0 | AP17: =IF((Lecturas!V15-Lecturas!U15)<= 0,"",Lecturas!V15-Lecturas!U15) | AQ17: =IFERROR(AP17*$AQ$3,"") -> 0 | AR17: =IF((Lecturas!W15-Lecturas!V15)<= 0,"",Lecturas!W15-Lecturas!V15) | AS17: =IFERROR(AR17*$AS$3,"") -> 0 | AT17: =IF((Lecturas!X15-Lecturas!W15)<= 0,"",Lecturas!X15-Lecturas!W15) | AU17: =IFERROR(AT17*$AU$3,"") -> 0 | AV17: =IF((Lecturas!Y15-Lecturas!X15)<= 0,"",Lecturas!Y15-Lecturas!X15) | AW17: =IFERROR(AV17*$AW$3,"") -> 0 | AX17: =IF((Lecturas!Z15-Lecturas!Y15)<= 0,"0",Lecturas!Z15-Lecturas!Y15) -> 0 | AY17: =IFERROR(AX17*$AY$3,"0") -> 0 | AZ17: =IF((Lecturas!AA15-Lecturas!Z15)<= 0,"0",Lecturas!AA15-Lecturas!Z15) -> 0 | BA17: =IFERROR(AZ17*$BA$3,"0") -> 0 | BB17: =IF((Lecturas!AB15-Lecturas!AA15)<= 0,"0",Lecturas!AB15-Lecturas!AA15) -> 0.001 | BC17: =IFERROR(BB17*$BC$3,"0") -> 0.014985666 | BD17: =IF((Lecturas!AC15-Lecturas!AB15)<= 0,"0",Lecturas!AC15-Lecturas!AB15) -> 0 | BE17: =IFERROR(BD17*$BE$3,"0") -> 0 | BF17: =IF((Lecturas!AD15-Lecturas!AC15)<= 0,"0",Lecturas!AD15-Lecturas!AC15) -> 0 | BG17: =IFERROR(BF17*$BG$3,"0") -> 0 | BH17: =IF((Lecturas!AE15-Lecturas!AD15)<= 0,"0",Lecturas!AE15-Lecturas!AD15) -> 0 | BI17: =IFERROR(BH17*$BI$3,"0") -> 0 | BJ17: =IF((Lecturas!AF15-Lecturas!AE15)<= 0,"0",Lecturas!AF15-Lecturas!AE15) -> 0 | BK17: =IFERROR(BJ17*$BK$3,"0") -> 0 | BL17: =IF((Lecturas!AG15-Lecturas!AF15)<= 0,"0",Lecturas!AG15-Lecturas!AF15) -> 0 | BM17: =IFERROR(BL17*$BM$3,"0") -> 0 | BN17: =IF((Lecturas!AH15-Lecturas!AG15)<= 0,"0",Lecturas!AH15-Lecturas!AG15) -> 0 | BO17: =IFERROR(BN17*$BO$3,"0") -> 0
A18: =ROUND(AG18,1) -> 0 | B18: =AF18 -> 0 | C18: 306 | D18: JOSE LLERENA RODRIGUEZ | E18: 2034050 | F18: =Lecturas!D16-Lecturas!C16 -> 0 | G18: =F18*$G$3 -> 0 | H18: =IF((Lecturas!E16-Lecturas!D16) < 0, "", Lecturas!E16-Lecturas!D16) -> 0 | I18: =IFERROR(H18*$I$3,"") -> 0 | J18: =IF(OR((Lecturas!F16-Lecturas!E16) < 0), "", Lecturas!F16-Lecturas!E16) -> 0 | K18: =IFERROR(J18*$K$3,"") -> 0 | L18: =IF(OR((Lecturas!G16-Lecturas!F16) < 0), "", Lecturas!G16-Lecturas!F16) -> 0 | M18: =IFERROR(L18*$M$3,"") -> 0 | N18: =IF(OR((Lecturas!H16-Lecturas!G16) < 0), "", Lecturas!H16-Lecturas!G16) -> 0 | O18: =IFERROR(N18*$O$3,"") -> 0 | P18: =IF(OR((Lecturas!I16-Lecturas!H16) < 0), "", Lecturas!I16-Lecturas!H16) -> 0 | Q18: =IFERROR(P18*$Q$3,"") -> 0 | R18: =IF(OR((Lecturas!J16-Lecturas!I16) < 0), "", Lecturas!J16-Lecturas!I16) -> 0 | S18: =IFERROR(R18*$S$3,"") -> 0 | T18: =IF(OR((Lecturas!K16-Lecturas!J16) < 0), "", Lecturas!K16-Lecturas!J16) -> 0 | U18: =IFERROR(T18*$U$3,"") -> 0 | V18: =IF(OR((Lecturas!L16-Lecturas!K16) < 0), "", Lecturas!L16-Lecturas!K16) -> 0 | W18: =IFERROR(V18*$W$3,"") -> 0 | X18: =IF(OR((Lecturas!M16-Lecturas!L16) < 0), "", Lecturas!M16-Lecturas!L16) -> 0 | Y18: =IFERROR(X18*$Y$3,"") -> 0 | Z18: =IF(OR((Lecturas!N16-Lecturas!M16) < 0), "", Lecturas!N16-Lecturas!M16) -> 0 | AA18: =IFERROR(Z18*$AA$3,"") -> 0 | AB18: =IF(OR((Lecturas!O16-Lecturas!N16) < 0), "", Lecturas!O16-Lecturas!N16) -> 0 | AC18: =IFERROR(AB18*$AC$3,"") -> 0 | AD18: =IF(OR((Lecturas!P16-Lecturas!O16) < 0), "", Lecturas!P16-Lecturas!O16) -> 0 | AE18: =IFERROR(AD18*$AE$3,"") -> 0 | AF18: =IF((Lecturas!Q16-Lecturas!P16)< 0,"",Lecturas!Q16-Lecturas!P16) -> 0 | AG18: =IFERROR(AF18*$AG$3,"") -> 0 | AH18: 0 | AI18: =IFERROR(AH18*$AI$3,"") -> 0 | AJ18: =IF((Lecturas!S16-Lecturas!R16)<= 0,"",Lecturas!S16-Lecturas!R16) | AK18: =IFERROR(AJ18*$AK$3,"") -> 0 | AL18: =IF((Lecturas!T16-Lecturas!S16)<= 0,"",Lecturas!T16-Lecturas!S16) | AM18: =IFERROR(AL18*$AM$3,"") -> 0 | AN18: =IF((Lecturas!U16-Lecturas!T16)<= 0,"",Lecturas!U16-Lecturas!T16) | AO18: =IFERROR(AN18*$AO$3,"") -> 0 | AP18: =IF((Lecturas!V16-Lecturas!U16)<= 0,"",Lecturas!V16-Lecturas!U16) | AQ18: =IFERROR(AP18*$AQ$3,"") -> 0 | AR18: =IF((Lecturas!W16-Lecturas!V16)<= 0,"",Lecturas!W16-Lecturas!V16) | AS18: =IFERROR(AR18*$AS$3,"") -> 0 | AT18: =IF((Lecturas!X16-Lecturas!W16)<= 0,"",Lecturas!X16-Lecturas!W16) | AU18: =IFERROR(AT18*$AU$3,"") -> 0 | AV18: =IF((Lecturas!Y16-Lecturas!X16)<= 0,"",Lecturas!Y16-Lecturas!X16) | AW18: =IFERROR(AV18*$AW$3,"") -> 0 | AX18: =IF((Lecturas!Z16-Lecturas!Y16)<= 0,"0",Lecturas!Z16-Lecturas!Y16) -> 0 | AY18: =IFERROR(AX18*$AY$3,"0") -> 0 | AZ18: =IF((Lecturas!AA16-Lecturas!Z16)<= 0,"0",Lecturas!AA16-Lecturas!Z16) -> 0 | BA18: =IFERROR(AZ18*$BA$3,"0") -> 0 | BB18: =IF((Lecturas!AB16-Lecturas!AA16)<= 0,"0",Lecturas!AB16-Lecturas!AA16) -> 0 | BC18: =IFERROR(BB18*$BC$3,"0") -> 0 | BD18: =IF((Lecturas!AC16-Lecturas!AB16)<= 0,"0",Lecturas!AC16-Lecturas!AB16) -> 0 | BE18: =IFERROR(BD18*$BE$3,"0") -> 0 | BF18: =IF((Lecturas!AD16-Lecturas!AC16)<= 0,"0",Lecturas!AD16-Lecturas!AC16) -> 0 | BG18: =IFERROR(BF18*$BG$3,"0") -> 0 | BH18: =IF((Lecturas!AE16-Lecturas!AD16)<= 0,"0",Lecturas!AE16-Lecturas!AD16) -> 0 | BI18: =IFERROR(BH18*$BI$3,"0") -> 0 | BJ18: =IF((Lecturas!AF16-Lecturas!AE16)<= 0,"0",Lecturas!AF16-Lecturas!AE16) -> 0 | BK18: =IFERROR(BJ18*$BK$3,"0") -> 0 | BL18: =IF((Lecturas!AG16-Lecturas!AF16)<= 0,"0",Lecturas!AG16-Lecturas!AF16) -> 0 | BM18: =IFERROR(BL18*$BM$3,"0") -> 0 | BN18: =IF((Lecturas!AH16-Lecturas!AG16)<= 0,"0",Lecturas!AH16-Lecturas!AG16) -> 0 | BO18: =IFERROR(BN18*$BO$3,"0") -> 0
A19: =ROUND(AG19,1) -> 9.5 | B19: =AF19 -> 0.666 | C19: 402 | D19: GARREAUD INDACOCHEA MARIA ELENA | E19: 2034057 | F19: =Lecturas!D17-Lecturas!C17 -> 2.866 | G19: =F19*$G$3 -> 64.014767 | H19: =IF((Lecturas!E17-Lecturas!D17) < 0, "", Lecturas!E17-Lecturas!D17) -> 2.958 | I19: =IFERROR(H19*$I$3,"") -> 52.84671 | J19: =IF(OR((Lecturas!F17-Lecturas!E17) <= 0), "", Lecturas!F17-Lecturas!E17) -> 2.77 | K19: =IFERROR(J19*$K$3,"") -> 33.685485 | L19: =IF(OR((Lecturas!G17-Lecturas!F17) <= 0), "", Lecturas!G17-Lecturas!F17) -> 3.926 | M19: =IFERROR(L19*$M$3,"") -> 61.287359 | N19: =IF(OR((Lecturas!H17-Lecturas!G17) <= 0), "", Lecturas!H17-Lecturas!G17) -> 9.96 | O19: =IFERROR(N19*$O$3,"") -> 151.35886 | P19: =IF(OR((Lecturas!I17-Lecturas!H17) <= 0), "", Lecturas!I17-Lecturas!H17) -> 7.319 | Q19: =IFERROR(P19*$Q$3,"") -> 108.62089 | R19: =IF(OR((Lecturas!J17-Lecturas!I17) <= 0), "", Lecturas!J17-Lecturas!I17) -> 6.293 | S19: =IFERROR(R19*$S$3,"") -> 104.28462 | T19: =IF(OR((Lecturas!K17-Lecturas!J17) <= 0), "", Lecturas!K17-Lecturas!J17) -> 4.278 | U19: =IFERROR(T19*$U$3,"") -> 75.130509 | V19: =IF(OR((Lecturas!L17-Lecturas!K17) < 0), "", Lecturas!L17-Lecturas!K17) -> 4.653 | W19: =IFERROR(V19*$W$3,"") -> 56.875827 | X19: =IF(OR((Lecturas!M17-Lecturas!L17) < 0), "", Lecturas!M17-Lecturas!L17) -> 1.431 | Y19: =IFERROR(X19*$Y$3,"") -> 17.364293 | Z19: =IF(OR((Lecturas!N17-Lecturas!M17) <= 0), "", Lecturas!N17-Lecturas!M17) -> 4.414 | AA19: =IFERROR(Z19*$AA$3,"") -> 62.177024 | AB19: =IF(OR((Lecturas!O17-Lecturas!N17) < 0), "", Lecturas!O17-Lecturas!N17) -> 5.163 | AC19: =IFERROR(AB19*$AC$3,"") -> 66.329263 | AD19: =IF(OR((Lecturas!P17-Lecturas!O17) < 0), "", Lecturas!P17-Lecturas!O17) -> 4.288 | AE19: =IFERROR(AD19*$AE$3,"") -> 53.935263 | AF19: =IF((Lecturas!Q17-Lecturas!P17)<= 0,"",Lecturas!Q17-Lecturas!P17) -> 0.666 | AG19: =IFERROR(AF19*$AG$3,"") -> 9.4891019 | AH19: =IF((Lecturas!R17-Lecturas!Q17)<= 0,"",Lecturas!R17-Lecturas!Q17) -> 3.444 | AI19: =IFERROR(AH19*$AI$3,"") -> 47.919667 | AJ19: =IF((Lecturas!S17-Lecturas!R17)<= 0,"",Lecturas!S17-Lecturas!R17) -> 1.822 | AK19: =IFERROR(AJ19*$AK$3,"") -> 26.2509 | AL19: =IF((Lecturas!T17-Lecturas!S17)<= 0,"",Lecturas!T17-Lecturas!S17) -> 3.135 | AM19: =IFERROR(AL19*$AM$3,"") -> 31.126862 | AN19: =IF((Lecturas!U17-Lecturas!T17)<= 0,"",Lecturas!U17-Lecturas!T17) -> 1.449 | AO19: =IFERROR(AN19*$AO$3,"") -> 23.564999 | AP19: =IF((Lecturas!V17-Lecturas!U17)<= 0,"",Lecturas!V17-Lecturas!U17) -> 3.958 | AQ19: =IFERROR(AP19*$AQ$3,"") -> 52.733344 | AR19: =IF((Lecturas!W17-Lecturas!V17)<= 0,"",Lecturas!W17-Lecturas!V17) -> 3.174 | AS19: =IFERROR(AR19*$AS$3,"") -> 37.506924 | AT19: =IF((Lecturas!X17-Lecturas!W17)<= 0,"",Lecturas!X17-Lecturas!W17) -> 4.635 | AU19: =IFERROR(AT19*$AU$3,"") -> 55.736769 | AV19: =IF((Lecturas!Y17-Lecturas!X17)<= 0,"",Lecturas!Y17-Lecturas!X17) -> 4.841 | AW19: =IFERROR(AV19*$AW$3,"") -> 59.34317 | AX19: =IF((Lecturas!Z17-Lecturas!Y17)<= 0,"0",Lecturas!Z17-Lecturas!Y17) -> 0.664 | AY19: =IFERROR(AX19*$AY$3,"0") -> 7.7050985 | AZ19: =IF((Lecturas!AA17-Lecturas!Z17)<= 0,"0",Lecturas!AA17-Lecturas!Z17) -> 1.813 | BA19: =IFERROR(AZ19*$BA$3,"0") -> 25.026708 | BB19: =IF((Lecturas!AB17-Lecturas!AA17)<= 0,"0",Lecturas!AB17-Lecturas!AA17) -> 2.705 | BC19: =IFERROR(BB19*$BC$3,"0") -> 40.536226 | BD19: =IF((Lecturas!AC17-Lecturas!AB17)<= 0,"0",Lecturas!AC17-Lecturas!AB17) -> 2.887 | BE19: =IFERROR(BD19*$BE$3,"0") -> 62.402556 | BF19: =IF((Lecturas!AD17-Lecturas!AC17)<= 0,"0",Lecturas!AD17-Lecturas!AC17) -> 0 | BG19: =IFERROR(BF19*$BG$3,"0") -> 0 | BH19: =IF((Lecturas!AE17-Lecturas!AD17)<= 0,"0",Lecturas!AE17-Lecturas!AD17) -> 0 | BI19: =IFERROR(BH19*$BI$3,"0") -> 0 | BJ19: =IF((Lecturas!AF17-Lecturas!AE17)<= 0,"0",Lecturas!AF17-Lecturas!AE17) -> 0 | BK19: =IFERROR(BJ19*$BK$3,"0") -> 0 | BL19: =IF((Lecturas!AG17-Lecturas!AF17)<= 0,"0",Lecturas!AG17-Lecturas!AF17) -> 0 | BM19: =IFERROR(BL19*$BM$3,"0") -> 0 | BN19: =IF((Lecturas!AH17-Lecturas!AG17)<= 0,"0",Lecturas!AH17-Lecturas!AG17) -> 0 | BO19: =IFERROR(BN19*$BO$3,"0") -> 0
